Workbook

Sheet VoiceBreak
D1: Date >> | E1: =TEXT(NOW(),"MM/DD/YYYY") -> 05/01/2026 | F1: Schedule
A2: EDS | B2: Task | C2: Agent | D2: Log In | E2: Break 1 | F2: Lunch | G2: Break 2
A3: C818 | B3: {=XLOOKUP(A3,Roster!F:F,Roster!A:A,"",0)} -> Mateo Henao | C3: {=XLOOKUP(A3,Roster!F:F,Roster!B:B,"",0)} -> Adriana Moncaleano | D3: {=XLOOKUP(A3&INT($E$1),BvsL!A:A,BvsL!F:F,"",0)} | E3: {=XLOOKUP(A3&INT($E$1),BvsL!A:A,BvsL!H:H,"",0)} | F3: {=XLOOKUP(A3&INT($E$1),BvsL!A:A,BvsL!I:I,"",0)} | G3: {=XLOOKUP(A3&INT($E$1),BvsL!A:A,BvsL!J:J,"",0)} | H3: {=XLOOKUP(A3,Roster!F:F,Roster!D:D,"",0)} -> 23 | I3: {=XLOOKUP(A3,Roster!F:F,Roster!E:E,"",0)} -> Voice
A4: C1107 | B4: {=XLOOKUP(A4,Roster!F:F,Roster!A:A,"",0)} -> Daniel Bustamante | C4: {=XLOOKUP(A4,Roster!F:F,Roster!B:B,"",0)} -> Alejandro Malave | D4: {=XLOOKUP(A4&INT($E$1),BvsL!A:A,BvsL!F:F,"",0)} | E4: {=XLOOKUP(A4&INT($E$1),BvsL!A:A,BvsL!H:H,"",0)} | F4: {=XLOOKUP(A4&INT($E$1),BvsL!A:A,BvsL!I:I,"",0)} | G4: {=XLOOKUP(A4&INT($E$1),BvsL!A:A,BvsL!J:J,"",0)} | H4: {=XLOOKUP(A4,Roster!F:F,Roster!D:D,"",0)} -> 36 | I4: {=XLOOKUP(A4,Roster!F:F,Roster!E:E,"",0)} -> Voice
A5: C1570 | B5: {=XLOOKUP(A5,Roster!F:F,Roster!A:A,"",0)} -> Mateo Henao | C5: {=XLOOKUP(A5,Roster!F:F,Roster!B:B,"",0)} -> Alexander Bartoli | D5: {=XLOOKUP(A5&INT($E$1),BvsL!A:A,BvsL!F:F,"",0)} | E5: {=XLOOKUP(A5&INT($E$1),BvsL!A:A,BvsL!H:H,"",0)} | F5: {=XLOOKUP(A5&INT($E$1),BvsL!A:A,BvsL!I:I,"",0)} | G5: {=XLOOKUP(A5&INT($E$1),BvsL!A:A,BvsL!J:J,"",0)} | H5: {=XLOOKUP(A5,Roster!F:F,Roster!D:D,"",0)} -> 38 | I5: {=XLOOKUP(A5,Roster!F:F,Roster!E:E,"",0)} -> Voice
A6: C1574 | B6: {=XLOOKUP(A6,Roster!F:F,Roster!A:A,"",0)} -> Mateo Henao | C6: {=XLOOKUP(A6,Roster!F:F,Roster!B:B,"",0)} -> Ana Quintero | D6: {=XLOOKUP(A6&INT($E$1),BvsL!A:A,BvsL!F:F,"",0)} | E6: {=XLOOKUP(A6&INT($E$1),BvsL!A:A,BvsL!H:H,"",0)} | F6: {=XLOOKUP(A6&INT($E$1),BvsL!A:A,BvsL!I:I,"",0)} | G6: {=XLOOKUP(A6&INT($E$1),BvsL!A:A,BvsL!J:J,"",0)} | H6: {=XLOOKUP(A6,Roster!F:F,Roster!D:D,"",0)} -> 38 | I6: {=XLOOKUP(A6,Roster!F:F,Roster!E:E,"",0)} -> Voice
A7: C1554 | B7: {=XLOOKUP(A7,Roster!F:F,Roster!A:A,"",0)} -> Mateo Henao | C7: {=XLOOKUP(A7,Roster!F:F,Roster!B:B,"",0)} -> Andres Lopez | D7: {=XLOOKUP(A7&INT($E$1),BvsL!A:A,BvsL!F:F,"",0)} | E7: {=XLOOKUP(A7&INT($E$1),BvsL!A:A,BvsL!H:H,"",0)} | F7: {=XLOOKUP(A7&INT($E$1),BvsL!A:A,BvsL!I:I,"",0)} | G7: {=XLOOKUP(A7&INT($E$1),BvsL!A:A,BvsL!J:J,"",0)} | H7: {=XLOOKUP(A7,Roster!F:F,Roster!D:D,"",0)} -> 37 | I7: {=XLOOKUP(A7,Roster!F:F,Roster!E:E,"",0)} -> Voice
A8: C1567 | B8: {=XLOOKUP(A8,Roster!F:F,Roster!A:A,"",0)} -> Mateo Henao | C8: {=XLOOKUP(A8,Roster!F:F,Roster!B:B,"",0)} -> Andres Salazar | D8: {=XLOOKUP(A8&INT($E$1),BvsL!A:A,BvsL!F:F,"",0)} | E8: {=XLOOKUP(A8&INT($E$1),BvsL!A:A,BvsL!H:H,"",0)} | F8: {=XLOOKUP(A8&INT($E$1),BvsL!A:A,BvsL!I:I,"",0)} | G8: {=XLOOKUP(A8&INT($E$1),BvsL!A:A,BvsL!J:J,"",0)} | H8: {=XLOOKUP(A8,Roster!F:F,Roster!D:D,"",0)} -> 38 | I8: {=XLOOKUP(A8,Roster!F:F,Roster!E:E,"",0)} -> Voice
A9: C1348 | B9: {=XLOOKUP(A9,Roster!F:F,Roster!A:A,"",0)} -> Mateo Henao | C9: {=XLOOKUP(A9,Roster!F:F,Roster!B:B,"",0)} -> Angelo Zapata | D9: {=XLOOKUP(A9&INT($E$1),BvsL!A:A,BvsL!F:F,"",0)} | E9: {=XLOOKUP(A9&INT($E$1),BvsL!A:A,BvsL!H:H,"",0)} | F9: {=XLOOKUP(A9&INT($E$1),BvsL!A:A,BvsL!I:I,"",0)} | G9: {=XLOOKUP(A9&INT($E$1),BvsL!A:A,BvsL!J:J,"",0)} | H9: {=XLOOKUP(A9,Roster!F:F,Roster!D:D,"",0)} -> 30 | I9: {=XLOOKUP(A9,Roster!F:F,Roster!E:E,"",0)} -> Voice
A10: C1579 | B10: {=XLOOKUP(A10,Roster!F:F,Roster!A:A,"",0)} -> Mateo Henao | C10: {=XLOOKUP(A10,Roster!F:F,Roster!B:B,"",0)} -> Anibal Munoz | D10: {=XLOOKUP(A10&INT($E$1),BvsL!A:A,BvsL!F:F,"",0)} | E10: {=XLOOKUP(A10&INT($E$1),BvsL!A:A,BvsL!H:H,"",0)} | F10: {=XLOOKUP(A10&INT($E$1),BvsL!A:A,BvsL!I:I,"",0)} | G10: {=XLOOKUP(A10&INT($E$1),BvsL!A:A,BvsL!J:J,"",0)} | H10: {=XLOOKUP(A10,Roster!F:F,Roster!D:D,"",0)} -> 38 | I10: {=XLOOKUP(A10,Roster!F:F,Roster!E:E,"",0)} -> Voice
A11: C1077 | B11: {=XLOOKUP(A11,Roster!F:F,Roster!A:A,"",0)} -> Martin Salazar | C11: {=XLOOKUP(A11,Roster!F:F,Roster!B:B,"",0)} -> Brahian Prado | D11: {=XLOOKUP(A11&INT($E$1),BvsL!A:A,BvsL!F:F,"",0)} | E11: {=XLOOKUP(A11&INT($E$1),BvsL!A:A,BvsL!H:H,"",0)} | F11: {=XLOOKUP(A11&INT($E$1),BvsL!A:A,BvsL!I:I,"",0)} | G11: {=XLOOKUP(A11&INT($E$1),BvsL!A:A,BvsL!J:J,"",0)} | H11: {=XLOOKUP(A11,Roster!F:F,Roster!D:D,"",0)} -> 18 | I11: {=XLOOKUP(A11,Roster!F:F,Roster!E:E,"",0)} -> Voice
A12: C1191 | B12: {=XLOOKUP(A12,Roster!F:F,Roster!A:A,"",0)} -> Mateo Henao | C12: {=XLOOKUP(A12,Roster!F:F,Roster!B:B,"",0)} -> Brayan Montoya | D12: {=XLOOKUP(A12&INT($E$1),BvsL!A:A,BvsL!F:F,"",0)} | E12: {=XLOOKUP(A12&INT($E$1),BvsL!A:A,BvsL!H:H,"",0)} | F12: {=XLOOKUP(A12&INT($E$1),BvsL!A:A,BvsL!I:I,"",0)} | G12: {=XLOOKUP(A12&INT($E$1),BvsL!A:A,BvsL!J:J,"",0)} | H12: {=XLOOKUP(A12,Roster!F:F,Roster!D:D,"",0)} -> 25 | I12: {=XLOOKUP(A12,Roster!F:F,Roster!E:E,"",0)} -> Voice
A13: C1526 | B13: {=XLOOKUP(A13,Roster!F:F,Roster!A:A,"",0)} -> Mateo Henao | C13: {=XLOOKUP(A13,Roster!F:F,Roster!B:B,"",0)} -> Breitner Benitez | D13: {=XLOOKUP(A13&INT($E$1),BvsL!A:A,BvsL!F:F,"",0)} | E13: {=XLOOKUP(A13&INT($E$1),BvsL!A:A,BvsL!H:H,"",0)} | F13: {=XLOOKUP(A13&INT($E$1),BvsL!A:A,BvsL!I:I,"",0)} | G13: {=XLOOKUP(A13&INT($E$1),BvsL!A:A,BvsL!J:J,"",0)} | H13: {=XLOOKUP(A13,Roster!F:F,Roster!D:D,"",0)} -> 13 | I13: {=XLOOKUP(A13,Roster!F:F,Roster!E:E,"",0)} -> Voice
A14: C1535 | B14: {=XLOOKUP(A14,Roster!F:F,Roster!A:A,"",0)} -> Daniel Bustamante | C14: {=XLOOKUP(A14,Roster!F:F,Roster!B:B,"",0)} -> Carlos Alzate | D14: {=XLOOKUP(A14&INT($E$1),BvsL!A:A,BvsL!F:F,"",0)} | E14: {=XLOOKUP(A14&INT($E$1),BvsL!A:A,BvsL!H:H,"",0)} | F14: {=XLOOKUP(A14&INT($E$1),BvsL!A:A,BvsL!I:I,"",0)} | G14: {=XLOOKUP(A14&INT($E$1),BvsL!A:A,BvsL!J:J,"",0)} | H14: {=XLOOKUP(A14,Roster!F:F,Roster!D:D,"",0)} -> 36 | I14: {=XLOOKUP(A14,Roster!F:F,Roster!E:E,"",0)} -> Voice
... A79: C1539 | B79: {=XLOOKUP(A79,Roster!F:F,Roster!A:A,"",0)} -> Daniel Bustamante | C79: {=XLOOKUP(A79,Roster!F:F,Roster!B:B,"",0)} -> Yovanny Ceballos | D79: {=XLOOKUP(A79&INT($E$1),BvsL!A:A,BvsL!F:F,"",0)} | E79: {=XLOOKUP(A79&INT($E$1),BvsL!A:A,BvsL!H:H,"",0)} | F79: {=XLOOKUP(A79&INT($E$1),BvsL!A:A,BvsL!I:I,"",0)} | G79: {=XLOOKUP(A79&INT($E$1),BvsL!A:A,BvsL!J:J,"",0)} | H79: {=XLOOKUP(A79,Roster!F:F,Roster!D:D,"",0)} -> 36 | I79: {=XLOOKUP(A79,Roster!F:F,Roster!E:E,"",0)} -> Voice

Sheet TicketsBreak
A1: EDS | B1: Log In | C1: Agent | D1: LogIn | E1: Break 1 | F1: Lunch | G1: Break 2
A2: {=XLOOKUP(C2,BvsL!E:E,BvsL!D:D,"",0)} -> C699 | B2: =IFERROR(__xludf.DUMMYFUNCTION("INDEX(FILTER(BvsL!F:F,BvsL!D:D=A2),1)"),"08:00") -> 08:00 | C2: Alexa Arenas | D2: 08:00 | E2: 0.40625 | F2: 0.5 | G2: 0.65625
A3: {=XLOOKUP(C3,BvsL!E:E,BvsL!D:D,"",0)} -> C935 | B3: =IFERROR(__xludf.DUMMYFUNCTION("INDEX(FILTER(BvsL!F:F,BvsL!D:D=A3),2)"),"07:30") -> 07:30 | C3: Alexis Arias | D3: 09:00 | E3: 0.42708333 | F3: 0.53125 | G3: 0.64583333
A4: {=XLOOKUP(C4,BvsL!E:E,BvsL!D:D,"",0)} -> C727 | B4: =IFERROR(__xludf.DUMMYFUNCTION("INDEX(FILTER(BvsL!F:F,BvsL!D:D=A4),2)"),"VL") -> VL | C4: Ana Moreno | D4: 09:00 | E4: 0.41666667 | F4: 0.52083333 | G4: 0.65625
A5: {=XLOOKUP(C5,BvsL!E:E,BvsL!D:D,"",0)} -> C469 | B5: =IFERROR(__xludf.DUMMYFUNCTION("INDEX(FILTER(BvsL!F:F,BvsL!D:D=A5),2)"),"08:00") -> 08:00 | C5: Ana Ruiz | D5: 09:00 | E5: 0.38541667 | F5: 0.5 | G5: 0.60416667
A6: {=XLOOKUP(C6,BvsL!E:E,BvsL!D:D,"",0)} -> C080 | B6: =IFERROR(__xludf.DUMMYFUNCTION("INDEX(FILTER(BvsL!F:F,BvsL!D:D=A6),1)"),"08:00") -> 08:00 | C6: Arturo Padilla | D6: 09:00 | E6: 0.375 | F6: 0.5 | G6: 0.64583333
A7: {=XLOOKUP(C7,BvsL!E:E,BvsL!D:D,"",0)} -> C1165 | B7: =IFERROR(__xludf.DUMMYFUNCTION("INDEX(FILTER(BvsL!F:F,BvsL!D:D=A7),1)"),"Free") -> Free | C7: Braian Restrepo | D7: 09:00
A8: {=XLOOKUP(C8,BvsL!E:E,BvsL!D:D,"",0)} -> C479 | B8: =IFERROR(__xludf.DUMMYFUNCTION("INDEX(FILTER(BvsL!F:F,BvsL!D:D=A8),2)"),"Free") -> Free | C8: Carmen Grajales | D8: 09:00 | E8: 0.42708333 | F8: 0.53125 | G8: 0.65625
A9: {=XLOOKUP(C9,BvsL!E:E,BvsL!D:D,"",0)} -> C673 | B9: =IFERROR(__xludf.DUMMYFUNCTION("INDEX(FILTER(BvsL!F:F,BvsL!D:D=A9),2)"),"Free") -> Free | C9: Dahiana Cano | D9: 09:00 | E9: 0.45833333 | F9: 0.58333333 | G9: 0.65625
A10: {=XLOOKUP(C10,BvsL!E:E,BvsL!D:D,"",0)} | B10: =IFERROR(__xludf.DUMMYFUNCTION("INDEX(FILTER(BvsL!F:F,BvsL!D:D=A10),1)"),"") | C10: Daniel Durango | D10: 09:00 | E10: 0.42708333 | F10: 0.53125 | G10: 0.65625
A11: {=XLOOKUP(C11,BvsL!E:E,BvsL!D:D,"",0)} -> C1216 | B11: =IFERROR(__xludf.DUMMYFUNCTION("INDEX(FILTER(BvsL!F:F,BvsL!D:D=A11),1)"),"08:00") -> 08:00 | C11: Eliana Pena | D11: 09:00 | E11: 0.39583333 | F11: 0.54166667 | G11: 0.63541667
A12: {=XLOOKUP(C12,BvsL!E:E,BvsL!D:D,"",0)} | B12: =IFERROR(__xludf.DUMMYFUNCTION("INDEX(FILTER(BvsL!F:F,BvsL!D:D=A12),2)"),"") | C12: Gabriel Atehortua | D12: 07:00
A13: {=XLOOKUP(C13,BvsL!E:E,BvsL!D:D,"",0)} -> C860 | B13: =IFERROR(__xludf.DUMMYFUNCTION("INDEX(FILTER(BvsL!F:F,BvsL!D:D=A13),2)"),"08:00") -> 08:00 | C13: Ief Fabre | D13: 09:00 | E13: 0.41666667 | F13: 0.5 | G13: 0.625
A14: {=XLOOKUP(C14,BvsL!E:E,BvsL!D:D,"",0)} -> C1027 | B14: =IFERROR(__xludf.DUMMYFUNCTION("INDEX(FILTER(BvsL!F:F,BvsL!D:D=A14),1)"),"VL") -> VL | C14: Jose Perez | D14: 06:00 | E14: 0.41666667 | F14: 0.52083333 | G14: 0.63541667
A15: {=XLOOKUP(C15,BvsL!E:E,BvsL!D:D,"",0)} -> C720 | B15: =IFERROR(__xludf.DUMMYFUNCTION("INDEX(FILTER(BvsL!F:F,BvsL!D:D=A15),2)"),"Free") -> Free | C15: Juan Durango | D15: 09:00 | E15: 0.40625 | F15: 0.57291667 | G15: 0.65625
A16: {=XLOOKUP(C16,BvsL!E:E,BvsL!D:D,"",0)} -> C598 | B16: =IFERROR(__xludf.DUMMYFUNCTION("INDEX(FILTER(BvsL!F:F,BvsL!D:D=A16),2)"),"") | C16: Juan Fonnegra | D16: 09:00 | E16: 0.41666667 | F16: 0.52083333 | G16: 0.65625
A17: {=XLOOKUP(C17,BvsL!E:E,BvsL!D:D,"",0)} | B17: =IFERROR(__xludf.DUMMYFUNCTION("INDEX(FILTER(BvsL!F:F,BvsL!D:D=A17),2)"),"") | C17: Juan Gutierrez | D17: 09:00 | E17: 0.4375 | F17: 0.58333333 | G17: 0.65625
A18: {=XLOOKUP(C18,BvsL!E:E,BvsL!D:D,"",0)} -> C743 | B18: =IFERROR(__xludf.DUMMYFUNCTION("INDEX(FILTER(BvsL!F:F,BvsL!D:D=A18),2)"),"08:30") -> 08:30 | C18: Juan Suarez | D18: 09:00 | E18: 0.39583333 | F18: 0.52083333 | G18: 0.61458333
A19: {=XLOOKUP(C19,BvsL!E:E,BvsL!D:D,"",0)} -> C579 | B19: =IFERROR(__xludf.DUMMYFUNCTION("INDEX(FILTER(BvsL!F:F,BvsL!D:D=A19),1)"),"Free") -> Free | C19: Karen Martinez | D19: 09:00 | E19: 0.41666667 | F19: 0.5 | G19: 0.625
A20: {=XLOOKUP(C20,BvsL!E:E,BvsL!D:D,"",0)} | B20: =IFERROR(__xludf.DUMMYFUNCTION("INDEX(FILTER(BvsL!F:F,BvsL!D:D=A20),1)"),"") | C20: Laura Moreno | D20: 09:00 | E20: 0.40625 | F20: 0.54166667 | G20: 0.625
A21: {=XLOOKUP(C21,BvsL!E:E,BvsL!D:D,"",0)} -> C534 | B21: =IFERROR(__xludf.DUMMYFUNCTION("INDEX(FILTER(BvsL!F:F,BvsL!D:D=A21),2)"),"08:00") -> 08:00 | C21: Leandry La Rosa | D21: 09:00 | E21: 0.40625 | F21: 0.54166667 | G21: 0.65625
A22: {=XLOOKUP(C22,BvsL!E:E,BvsL!D:D,"",0)} -> C535 | B22: =IFERROR(__xludf.DUMMYFUNCTION("INDEX(FILTER(BvsL!F:F,BvsL!D:D=A22),2)"),"08:00") -> 08:00 | C22: Lina Cadena | D22: 09:00 | E22: 0.38541667 | F22: 0.58333333 | G22: 0.64583333
A23: {=XLOOKUP(C23,BvsL!E:E,BvsL!D:D,"",0)} -> C740 | B23: =IFERROR(__xludf.DUMMYFUNCTION("INDEX(FILTER(BvsL!F:F,BvsL!D:D=A23),1)"),"08:00") -> 08:00 | C23: Mateo Agudelo | D23: 09:00 | E23: 0.41666667 | F23: 0.5 | G23: 0.65625
A24: {=XLOOKUP(C24,BvsL!E:E,BvsL!D:D,"",0)} -> C1065 | B24: =IFERROR(__xludf.DUMMYFUNCTION("INDEX(FILTER(BvsL!F:F,BvsL!D:D=A24),1)"),"07:00") -> 07:00 | C24: Miguel Hoyos | D24: 09:00 | E24: 0.45833333 | F24: 0.5625 | G24: 0.65625
A25: {=XLOOKUP(C25,BvsL!E:E,BvsL!D:D,"",0)} -> C556 | B25: =IFERROR(__xludf.DUMMYFUNCTION("INDEX(FILTER(BvsL!F:F,BvsL!D:D=A25),1)"),"08:00") -> 08:00 | C25: Nelson Londono | D25: 09:00 | E25: 0.38541667 | F25: 0.58333333 | G25: 0.64583333
A26: {=XLOOKUP(C26,BvsL!E:E,BvsL!D:D,"",0)} -> C714 | B26: =IFERROR(__xludf.DUMMYFUNCTION("INDEX(FILTER(BvsL!F:F,BvsL!D:D=A26),2)"),"08:00") -> 08:00 | C26: Onel Olivera | D26: 09:00 | E26: 0.41666667 | F26: 0.5 | G26: 0.625
A27: {=XLOOKUP(C27,BvsL!E:E,BvsL!D:D,"",0)} | B27: =IFERROR(__xludf.DUMMYFUNCTION("INDEX(FILTER(BvsL!F:F,BvsL!D:D=A27),1)"),"") | C27: Santiago Garcia | D27: 09:00 | E27: 0.38541667 | F27: 0.5 | G27: 0.60416667
A28: {=XLOOKUP(C28,BvsL!E:E,BvsL!D:D,"",0)} -> C1220 | B28: =IFERROR(__xludf.DUMMYFUNCTION("INDEX(FILTER(BvsL!F:F,BvsL!D:D=A28),1)"),"08:00") -> 08:00 | C28: Santiago Gonzalez | D28: 09:00
A29: {=XLOOKUP(C29,BvsL!E:E,BvsL!D:D,"",0)} -> C1199 | B29: =IFERROR(__xludf.DUMMYFUNCTION("INDEX(FILTER(BvsL!F:F,BvsL!D:D=A29),1)"),"08:00") -> 08:00 | C29: Santiago Velasquez | D29: 09:00
A30: {=XLOOKUP(C30,BvsL!E:E,BvsL!D:D,"",0)} -> C902 | B30: =IFERROR(__xludf.DUMMYFUNCTION("INDEX(FILTER(BvsL!F:F,BvsL!D:D=A30),1)"),"08:00") -> 08:00 | C30: Sebastiam Vallejo | D30: 09:00 | E30: 0.4375 | F30: 0.60416667 | G30: 0.65625
A31: {=XLOOKUP(C31,BvsL!E:E,BvsL!D:D,"",0)} -> C1190 | B31: =IFERROR(__xludf.DUMMYFUNCTION("INDEX(FILTER(BvsL!F:F,BvsL!D:D=A31),2)"),"07:00") -> 07:00 | C31: Sebastian Herrera | D31: 07:00 | E31: 0.40625 | F31: 0.54166667 | G31: 0.625
A32: {=XLOOKUP(C32,BvsL!E:E,BvsL!D:D,"",0)} -> C710 | B32: =IFERROR(__xludf.DUMMYFUNCTION("INDEX(FILTER(BvsL!F:F,BvsL!D:D=A32),2)"),"08:00") -> 08:00 | C32: Sebastian Martinez | D32: 08:00 | E32: 0.40625 | F32: 0.5625 | G32: 0.65625
A33: {=XLOOKUP(C33,BvsL!E:E,BvsL!D:D,"",0)} -> C723 | B33: =IFERROR(__xludf.DUMMYFUNCTION("INDEX(FILTER(BvsL!F:F,BvsL!D:D=A33),1)"),"VL") -> VL | C33: Sebastian Parra | D33: 09:00 | E33: 0.41666667 | F33: 0.53472222 | G33: 0.65625
A34: {=XLOOKUP(C34,BvsL!E:E,BvsL!D:D,"",0)} -> C1376 | B34: =IFERROR(__xludf.DUMMYFUNCTION("INDEX(FILTER(BvsL!F:F,BvsL!D:D=A34),2)"),"08:00") -> 08:00 | C34: Sebastian Quiroz | D34: 09:00
A35: {=XLOOKUP(C35,BvsL!E:E,BvsL!D:D,"",0)} -> C726 | B35: =IFERROR(__xludf.DUMMYFUNCTION("INDEX(FILTER(BvsL!F:F,BvsL!D:D=A35),1)"),"08:00") -> 08:00 | C35: Sebastian Rodriguez | D35: 09:00 | E35: 0.41666667 | F35: 0.5625 | G35: 0.64583333
A36: {=XLOOKUP(C36,BvsL!E:E,BvsL!D:D,"",0)} -> C602 | B36: =IFERROR(__xludf.DUMMYFUNCTION("INDEX(FILTER(BvsL!F:F,BvsL!D:D=A36),1)"),"08:00") -> 08:00 | C36: Sebastian Torres | D36: VL | E36: 0.45833333 | F36: 0.58333333 | G36: 0.65625
A37: {=XLOOKUP(C37,BvsL!E:E,BvsL!D:D,"",0)} -> C1478 | B37: =IFERROR(__xludf.DUMMYFUNCTION("INDEX(FILTER(BvsL!F:F,BvsL!D:D=A37),2)"),"07:00") -> 07:00 | C37: Simon Atehortua | D37: 08:00
A38: {=XLOOKUP(C38,BvsL!E:E,BvsL!D:D,"",0)} -> C1126 | B38: =IFERROR(__xludf.DUMMYFUNCTION("INDEX(FILTER(BvsL!F:F,BvsL!D:D=A38),1)"),"Free") -> Free | C38: Valery Escobar | D38: 09:00 | E38: 0.38541667 | F38: 0.5 | G38: 0.60416667
A39: {=XLOOKUP(C39,BvsL!E:E,BvsL!D:D,"",0)} -> C786 | B39: =IFERROR(__xludf.DUMMYFUNCTION("INDEX(FILTER(BvsL!F:F,BvsL!D:D=A39),1)"),"Free") -> Free | C39: Wendy Navarro | D39: 09:00 | E39: 0.41666667 | F39: 0.54166667 | G39: 0.64583333
A40: {=XLOOKUP(C40,BvsL!E:E,BvsL!D:D,"",0)} | B40: =IFERROR(__xludf.DUMMYFUNCTION("INDEX(FILTER(BvsL!F:F,BvsL!D:D=A40),2)"),"") | C40: William Venner | D40: 09:00 | E40: 0.44791667 | F40: 0.60416667 | G40: 0.64583333
...

Sheet Sheet33

Sheet Sheet34

Sheet Sheet32

Sheet OperationTickets
D1: 46138 | E1: 46139 | F1: 46140 | G1: 46141 | H1: 46142 | I1: 46143 | J1: 46144 | K1: 46145 | L1: 46146 | M1: 46147 | N1: 46148 | O1: 46149 | P1: 46150 | Q1: 46151 | R1: 46152 | S1: 46153 | T1: 46154 | U1: 46155 | V1: 46156 | W1: 46157 | X1: 46158 | Y1: 46159 | Z1: 46160 | AA1: 46161 | AB1: 46162 | AC1: 46163 | AD1: 46164 | AE1: 46165 | AF1: 46166 | AG1: 46167 | AH1: 46168 | AI1: 46169 | AJ1: 46170 | AK1: 46171 | AL1: 46172 | AM1: 46173
A2: EDS | B2: Team Leader | C2: Agent Name | D2: 45501 | E2: 45502 | F2: 45503 | G2: 45504 | H2: 45505 | I2: 45506 | J2: 45507 | K2: 45508 | L2: 45509 | M2: 45510 | N2: 45511 | O2: 45512 | P2: 45513 | Q2: 45514 | R2: 45515 | S2: 45516 | T2: 45517 | U2: 45518 | V2: 45519 | W2: 45520 | X2: 45521 | Y2: 45522 | Z2: 45523 | AA2: 45524 | AB2: 45525 | AC2: 45526 | AD2: 45527 | AE2: 45528 | AF2: 45529 | AG2: 45530 | AH2: 45531 | AI2: 45532 | AJ2: 45533 | AK2: 45534 | AL2: 45535 | AM2: 45536
A3: C1216 | B3: {=XLOOKUP(A3,Roster!F:F,Roster!A:A,"",0)} -> Edward Machado | C3: {=XLOOKUP(A3,Roster!F:F,Roster!B:B,"",0)} -> Eliana Pena | D3: B&B | E3: {=IF(XLOOKUP($A3,Partner_BookInBlock!$A:$A,Partner_BookInBlock!E:E,"",0)="Free","Free",IF(XLOOKUP($A3,Partner_BookInBlock!$A:$A,Partner_BookInBlock!E:E,"",0)="VL","VL",IF(XLOOKUP($A3,Partner_BookInBlock!$A:$A,Partner_BookInBlock!E:E,"",0)="ATT","ATT",XLOOKUP($A3,Partner_BookInBlock!$A:$A,Partner_BookInBlock!E:E,"",0))))} -> 0.33333333 | F3: {=IF(XLOOKUP($A3,Partner_BookInBlock!$A:$A,Partner_BookInBlock!F:F,"",0)="Free","Free",IF(XLOOKUP($A3,Partner_BookInBlock!$A:$A,Partner_BookInBlock!F:F,"",0)="VL","VL",IF(XLOOKUP($A3,Partner_BookInBlock!$A:$A,Partner_BookInBlock!F:F,"",0)="ATT","ATT",XLOOKUP($A3,Partner_BookInBlock!$A:$A,Partner_BookInBlock!F:F,"",0))))} -> 0.33333333 | G3: {=IF(XLOOKUP($A3,Partner_BookInBlock!$A:$A,Partner_BookInBlock!G:G,"",0)="Free","Free",IF(XLOOKUP($A3,Partner_BookInBlock!$A:$A,Partner_BookInBlock!G:G,"",0)="VL","VL",IF(XLOOKUP($A3,Partner_BookInBlock!$A:$A,Partner_BookInBlock!G:G,"",0)="ATT","ATT",XLOOKUP($A3,Partner_BookInBlock!$A:$A,Partner_BookInBlock!G:G,"",0))))} -> 0.33333333 | H3: {=IF(XLOOKUP($A3,Partner_BookInBlock!$A:$A,Partner_BookInBlock!H:H,"",0)="Free","Free",IF(XLOOKUP($A3,Partner_BookInBlock!$A:$A,Partner_BookInBlock!H:H,"",0)="VL","VL",IF(XLOOKUP($A3,Partner_BookInBlock!$A:$A,Partner_BookInBlock!H:H,"",0)="ATT","ATT",XLOOKUP($A3,Partner_BookInBlock!$A:$A,Partner_BookInBlock!H:H,"",0))))} -> Free | I3: {=IF(XLOOKUP($A3,Partner_BookInBlock!$A:$A,Partner_BookInBlock!I:I,"",0)="Free","Free",IF(XLOOKUP($A3,Partner_BookInBlock!$A:$A,Partner_BookInBlock!I:I,"",0)="VL","VL",IF(XLOOKUP($A3,Partner_BookInBlock!$A:$A,Partner_BookInBlock!I:I,"",0)="ATT","ATT",XLOOKUP($A3,Partner_BookInBlock!$A:$A,Partner_BookInBlock!I:I,"",0))))} -> 0.33333333 | J3: {=IF(XLOOKUP($A3,Partner_BookInBlock!$A:$A,Partner_BookInBlock!J:J,"",0)="Free","Free",IF(XLOOKUP($A3,Partner_BookInBlock!$A:$A,Partner_BookInBlock!J:J,"",0)="VL","VL",IF(XLOOKUP($A3,Partner_BookInBlock!$A:$A,Partner_BookInBlock!J:J,"",0)="ATT","ATT",XLOOKUP($A3,Partner_BookInBlock!$A:$A,Partner_BookInBlock!J:J,"",0))))} -> 0.33333333 | K3: {=IF(XLOOKUP($A3,Partner_BookInBlock!$A:$A,Partner_BookInBlock!K:K,"",0)="Free","Free",IF(XLOOKUP($A3,Partner_BookInBlock!$A:$A,Partner_BookInBlock!K:K,"",0)="VL","VL",IF(XLOOKUP($A3,Partner_BookInBlock!$A:$A,Partner_BookInBlock!K:K,"",0)="ATT","ATT",XLOOKUP($A3,Partner_BookInBlock!$A:$A,Partner_BookInBlock!K:K,"",0))))} | L3: {=IF(XLOOKUP($A3,Partner_BookInBlock!$A:$A,Partner_BookInBlock!L:L,"",0)="Free","Free",IF(XLOOKUP($A3,Partner_BookInBlock!$A:$A,Partner_BookInBlock!L:L,"",0)="VL","VL",IF(XLOOKUP($A3,Partner_BookInBlock!$A:$A,Partner_BookInBlock!L:L,"",0)="ATT","ATT",XLOOKUP($A3,Partner_BookInBlock!$A:$A,Partner_BookInBlock!L:L,"",0))))} -> 0.33333333 | M3: {=IF(XLOOKUP($A3,Partner_BookInBlock!$A:$A,Partner_BookInBlock!M:M,"",0)="Free","Free",IF(XLOOKUP($A3,Partner_BookInBlock!$A:$A,Partner_BookInBlock!M:M,"",0)="VL","VL",IF(XLOOKUP($A3,Partner_BookInBlock!$A:$A,Partner_BookInBlock!M:M,"",0)="ATT","ATT",XLOOKUP($A3,Partner_BookInBlock!$A:$A,Partner_BookInBlock!M:M,"",0))))} -> 0.33333333 | N3: {=IF(XLOOKUP($A3,Partner_BookInBlock!$A:$A,Partner_BookInBlock!N:N,"",0)="Free","Free",IF(XLOOKUP($A3,Partner_BookInBlock!$A:$A,Partner_BookInBlock!N:N,"",0)="VL","VL",IF(XLOOKUP($A3,Partner_BookInBlock!$A:$A,Partner_BookInBlock!N:N,"",0)="ATT","ATT",XLOOKUP($A3,Partner_BookInBlock!$A:$A,Partner_BookInBlock!N:N,"",0))))} -> 0.33333333 | O3: {=IF(XLOOKUP($A3,Partner_BookInBlock!$A:$A,Partner_BookInBlock!O:O,"",0)="Free","Free",IF(XLOOKUP($A3,Partner_BookInBlock!$A:$A,Partner_BookInBlock!O:O,"",0)="VL","VL",IF(XLOOKUP($A3,Partner_BookInBlock!$A:$A,Partner_BookInBlock!O:O,"",0)="ATT","ATT",XLOOKUP($A3,Partner_BookInBlock!$A:$A,Partner_BookInBlock!O:O,"",0))))} -> Free | P3: {=IF(XLOOKUP($A3,Partner_BookInBlock!$A:$A,Partner_BookInBlock!P:P,"",0)="Free","Free",IF(XLOOKUP($A3,Partner_BookInBlock!$A:$A,Partner_BookInBlock!P:P,"",0)="VL","VL",IF(XLOOKUP($A3,Partner_BookInBlock!$A:$A,Partner_BookInBlock!P:P,"",0)="ATT","ATT",XLOOKUP($A3,Partner_BookInBlock!$A:$A,Partner_BookInBlock!P:P,"",0))))} -> 0.33333333 | Q3: {=IF(XLOOKUP($A3,Partner_BookInBlock!$A:$A,Partner_BookInBlock!Q:Q,"",0)="Free","Free",IF(XLOOKUP($A3,Partner_BookInBlock!$A:$A,Partner_BookInBlock!Q:Q,"",0)="VL","VL",IF(XLOOKUP($A3,Partner_BookInBlock!$A:$A,Partner_BookInBlock!Q:Q,"",0)="ATT","ATT",XLOOKUP($A3,Partner_BookInBlock!$A:$A,Partner_BookInBlock!Q:Q,"",0))))} -> 0.33333333 | S3: {=IF(XLOOKUP($A3,Partner_BookInBlock!$A:$A,Partner_BookInBlock!S:S,"",0)="Free","Free",IF(XLOOKUP($A3,Partner_BookInBlock!$A:$A,Partner_BookInBlock!S:S,"",0)="VL","VL",IF(XLOOKUP($A3,Partner_BookInBlock!$A:$A,Partner_BookInBlock!S:S,"",0)="ATT","ATT",XLOOKUP($A3,Partner_BookInBlock!$A:$A,Partner_BookInBlock!S:S,"",0))))} -> 0.33333333 | T3: {=IF(XLOOKUP($A3,Partner_BookInBlock!$A:$A,Partner_BookInBlock!T:T,"",0)="Free","Free",IF(XLOOKUP($A3,Partner_BookInBlock!$A:$A,Partner_BookInBlock!T:T,"",0)="VL","VL",IF(XLOOKUP($A3,Partner_BookInBlock!$A:$A,Partner_BookInBlock!T:T,"",0)="ATT","ATT",XLOOKUP($A3,Partner_BookInBlock!$A:$A,Partner_BookInBlock!T:T,"",0))))} -> 0.33333333 | U3: {=IF(XLOOKUP($A3,Partner_BookInBlock!$A:$A,Partner_BookInBlock!U:U,"",0)="Free","Free",IF(XLOOKUP($A3,Partner_BookInBlock!$A:$A,Partner_BookInBlock!U:U,"",0)="VL","VL",IF(XLOOKUP($A3,Partner_BookInBlock!$A:$A,Partner_BookInBlock!U:U,"",0)="ATT","ATT",XLOOKUP($A3,Partner_BookInBlock!$A:$A,Partner_BookInBlock!U:U,"",0))))} -> 0.33333333 | V3: {=IF(XLOOKUP($A3,Partner_BookInBlock!$A:$A,Partner_BookInBlock!V:V,"",0)="Free","Free",IF(XLOOKUP($A3,Partner_BookInBlock!$A:$A,Partner_BookInBlock!V:V,"",0)="VL","VL",IF(XLOOKUP($A3,Partner_BookInBlock!$A:$A,Partner_BookInBlock!V:V,"",0)="ATT","ATT",XLOOKUP($A3,Partner_BookInBlock!$A:$A,Partner_BookInBlock!V:V,"",0))))} -> Free | W3: {=IF(XLOOKUP($A3,Partner_BookInBlock!$A:$A,Partner_BookInBlock!W:W,"",0)="Free","Free",IF(XLOOKUP($A3,Partner_BookInBlock!$A:$A,Partner_BookInBlock!W:W,"",0)="VL","VL",IF(XLOOKUP($A3,Partner_BookInBlock!$A:$A,Partner_BookInBlock!W:W,"",0)="ATT","ATT",XLOOKUP($A3,Partner_BookInBlock!$A:$A,Partner_BookInBlock!W:W,"",0))))} -> 0.33333333 | X3: {=IF(XLOOKUP($A3,Partner_BookInBlock!$A:$A,Partner_BookInBlock!X:X,"",0)="Free","Free",IF(XLOOKUP($A3,Partner_BookInBlock!$A:$A,Partner_BookInBlock!X:X,"",0)="VL","VL",IF(XLOOKUP($A3,Partner_BookInBlock!$A:$A,Partner_BookInBlock!X:X,"",0)="ATT","ATT",XLOOKUP($A3,Partner_BookInBlock!$A:$A,Partner_BookInBlock!X:X,"",0))))} -> 0.33333333 | Z3: {=IF(XLOOKUP($A3,Partner_BookInBlock!$A:$A,Partner_BookInBlock!Z:Z,"",0)="Free","Free",IF(XLOOKUP($A3,Partner_BookInBlock!$A:$A,Partner_BookInBlock!Z:Z,"",0)="VL","VL",IF(XLOOKUP($A3,Partner_BookInBlock!$A:$A,Partner_BookInBlock!Z:Z,"",0)="ATT","ATT",XLOOKUP($A3,Partner_BookInBlock!$A:$A,Partner_BookInBlock!Z:Z,"",0))))} -> 0.33333333 | AA3: {=IF(XLOOKUP($A3,Partner_BookInBlock!$A:$A,Partner_BookInBlock!AA:AA,"",0)="Free","Free",IF(XLOOKUP($A3,Partner_BookInBlock!$A:$A,Partner_BookInBlock!AA:AA,"",0)="VL","VL",IF(XLOOKUP($A3,Partner_BookInBlock!$A:$A,Partner_BookInBlock!AA:AA,"",0)="ATT","ATT",XLOOKUP($A3,Partner_BookInBlock!$A:$A,Partner_BookInBlock!AA:AA,"",0))))} -> 0.33333333 | AB3: {=IF(XLOOKUP($A3,Partner_BookInBlock!$A:$A,Partner_BookInBlock!AB:AB,"",0)="Free","Free",IF(XLOOKUP($A3,Partner_BookInBlock!$A:$A,Partner_BookInBlock!AB:AB,"",0)="VL","VL",IF(XLOOKUP($A3,Partner_BookInBlock!$A:$A,Partner_BookInBlock!AB:AB,"",0)="ATT","ATT",XLOOKUP($A3,Partner_BookInBlock!$A:$A,Partner_BookInBlock!AB:AB,"",0))))} -> 0.33333333 | AC3: {=IF(XLOOKUP($A3,Partner_BookInBlock!$A:$A,Partner_BookInBlock!AC:AC,"",0)="Free","Free",IF(XLOOKUP($A3,Partner_BookInBlock!$A:$A,Partner_BookInBlock!AC:AC,"",0)="VL","VL",IF(XLOOKUP($A3,Partner_BookInBlock!$A:$A,Partner_BookInBlock!AC:AC,"",0)="ATT","ATT",XLOOKUP($A3,Partner_BookInBlock!$A:$A,Partner_BookInBlock!AC:AC,"",0))))} -> Free | AD3: {=IF(XLOOKUP($A3,Partner_BookInBlock!$A:$A,Partner_BookInBlock!AD:AD,"",0)="Free","Free",IF(XLOOKUP($A3,Partner_BookInBlock!$A:$A,Partner_BookInBlock!AD:AD,"",0)="VL","VL",IF(XLOOKUP($A3,Partner_BookInBlock!$A:$A,Partner_BookInBlock!AD:AD,"",0)="ATT","ATT",XLOOKUP($A3,Partner_BookInBlock!$A:$A,Partner_BookInBlock!AD:AD,"",0))))} -> 0.33333333 | AE3: {=IF(XLOOKUP($A3,Partner_BookInBlock!$A:$A,Partner_BookInBlock!AE:AE,"",0)="Free","Free",IF(XLOOKUP($A3,Partner_BookInBlock!$A:$A,Partner_BookInBlock!AE:AE,"",0)="VL","VL",IF(XLOOKUP($A3,Partner_BookInBlock!$A:$A,Partner_BookInBlock!AE:AE,"",0)="ATT","ATT",XLOOKUP($A3,Partner_BookInBlock!$A:$A,Partner_BookInBlock!AE:AE,"",0))))} -> 0.33333333 | AG3: {=IF(XLOOKUP($A3,Partner_BookInBlock!$A:$A,Partner_BookInBlock!AG:AG,"",0)="Free","Free",IF(XLOOKUP($A3,Partner_BookInBlock!$A:$A,Partner_BookInBlock!AG:AG,"",0)="VL","VL",IF(XLOOKUP($A3,Partner_BookInBlock!$A:$A,Partner_BookInBlock!AG:AG,"",0)="ATT","ATT",XLOOKUP($A3,Partner_BookInBlock!$A:$A,Partner_BookInBlock!AG:AG,"",0))))} -> 0.33333333 | AH3: {=IF(XLOOKUP($A3,Partner_BookInBlock!$A:$A,Partner_BookInBlock!AH:AH,"",0)="Free","Free",IF(XLOOKUP($A3,Partner_BookInBlock!$A:$A,Partner_BookInBlock!AH:AH,"",0)="VL","VL",IF(XLOOKUP($A3,Partner_BookInBlock!$A:$A,Partner_BookInBlock!AH:AH,"",0)="ATT","ATT",XLOOKUP($A3,Partner_BookInBlock!$A:$A,Partner_BookInBlock!AH:AH,"",0))))} -> 0.33333333 | AI3: {=IF(XLOOKUP($A3,Partner_BookInBlock!$A:$A,Partner_BookInBlock!AI:AI,"",0)="Free","Free",IF(XLOOKUP($A3,Partner_BookInBlock!$A:$A,Partner_BookInBlock!AI:AI,"",0)="VL","VL",IF(XLOOKUP($A3,Partner_BookInBlock!$A:$A,Partner_BookInBlock!AI:AI,"",0)="ATT","ATT",XLOOKUP($A3,Partner_BookInBlock!$A:$A,Partner_BookInBlock!AI:AI,"",0))))} -> 0.33333333 | AJ3: {=IF(XLOOKUP($A3,Partner_BookInBlock!$A:$A,Partner_BookInBlock!AJ:AJ,"",0)="Free","Free",IF(XLOOKUP($A3,Partner_BookInBlock!$A:$A,Partner_BookInBlock!AJ:AJ,"",0)="VL","VL",IF(XLOOKUP($A3,Partner_BookInBlock!$A:$A,Partner_BookInBlock!AJ:AJ,"",0)="ATT","ATT",XLOOKUP($A3,Partner_BookInBlock!$A:$A,Partner_BookInBlock!AJ:AJ,"",0))))} -> Free | AK3: {=IF(XLOOKUP($A3,Partner_BookInBlock!$A:$A,Partner_BookInBlock!AK:AK,"",0)="Free","Free",IF(XLOOKUP($A3,Partner_BookInBlock!$A:$A,Partner_BookInBlock!AK:AK,"",0)="VL","VL",IF(XLOOKUP($A3,Partner_BookInBlock!$A:$A,Partner_BookInBlock!AK:AK,"",0)="ATT","ATT",XLOOKUP($A3,Partner_BookInBlock!$A:$A,Partner_BookInBlock!AK:AK,"",0))))} -> 0.33333333 | AL3: {=IF(XLOOKUP($A3,Partner_BookInBlock!$A:$A,Partner_BookInBlock!AL:AL,"",0)="Free","Free",IF(XLOOKUP($A3,Partner_BookInBlock!$A:$A,Partner_BookInBlock!AL:AL,"",0)="VL","VL",IF(XLOOKUP($A3,Partner_BookInBlock!$A:$A,Partner_BookInBlock!AL:AL,"",0)="ATT","ATT",XLOOKUP($A3,Partner_BookInBlock!$A:$A,Partner_BookInBlock!AL:AL,"",0))))} -> 0.33333333
A4: C786 | B4: {=XLOOKUP(A4,Roster!F:F,Roster!A:A,"",0)} -> Luis Vidal | C4: {=XLOOKUP(A4,Roster!F:F,Roster!B:B,"",0)} -> Wendy Navarro | D4: B&B | E4: {=IF(XLOOKUP($A4,Partner_BookInBlock!$A:$A,Partner_BookInBlock!E:E,"",0)="Free","Free",IF(XLOOKUP($A4,Partner_BookInBlock!$A:$A,Partner_BookInBlock!E:E,"",0)="VL","VL",IF(XLOOKUP($A4,Partner_BookInBlock!$A:$A,Partner_BookInBlock!E:E,"",0)="ATT","ATT",XLOOKUP($A4,Partner_BookInBlock!$A:$A,Partner_BookInBlock!E:E,"",0))))} -> 0.33333333 | F4: {=IF(XLOOKUP($A4,Partner_BookInBlock!$A:$A,Partner_BookInBlock!F:F,"",0)="Free","Free",IF(XLOOKUP($A4,Partner_BookInBlock!$A:$A,Partner_BookInBlock!F:F,"",0)="VL","VL",IF(XLOOKUP($A4,Partner_BookInBlock!$A:$A,Partner_BookInBlock!F:F,"",0)="ATT","ATT",XLOOKUP($A4,Partner_BookInBlock!$A:$A,Partner_BookInBlock!F:F,"",0))))} -> 0.33333333 | G4: {=IF(XLOOKUP($A4,Partner_BookInBlock!$A:$A,Partner_BookInBlock!G:G,"",0)="Free","Free",IF(XLOOKUP($A4,Partner_BookInBlock!$A:$A,Partner_BookInBlock!G:G,"",0)="VL","VL",IF(XLOOKUP($A4,Partner_BookInBlock!$A:$A,Partner_BookInBlock!G:G,"",0)="ATT","ATT",XLOOKUP($A4,Partner_BookInBlock!$A:$A,Partner_BookInBlock!G:G,"",0))))} -> Free | H4: {=IF(XLOOKUP($A4,Partner_BookInBlock!$A:$A,Partner_BookInBlock!H:H,"",0)="Free","Free",IF(XLOOKUP($A4,Partner_BookInBlock!$A:$A,Partner_BookInBlock!H:H,"",0)="VL","VL",IF(XLOOKUP($A4,Partner_BookInBlock!$A:$A,Partner_BookInBlock!H:H,"",0)="ATT","ATT",XLOOKUP($A4,Partner_BookInBlock!$A:$A,Partner_BookInBlock!H:H,"",0))))} -> 0.33333333 | I4: {=IF(XLOOKUP($A4,Partner_BookInBlock!$A:$A,Partner_BookInBlock!I:I,"",0)="Free","Free",IF(XLOOKUP($A4,Partner_BookInBlock!$A:$A,Partner_BookInBlock!I:I,"",0)="VL","VL",IF(XLOOKUP($A4,Partner_BookInBlock!$A:$A,Partner_BookInBlock!I:I,"",0)="ATT","ATT",XLOOKUP($A4,Partner_BookInBlock!$A:$A,Partner_BookInBlock!I:I,"",0))))} -> 0.33333333 | J4: {=IF(XLOOKUP($A4,Partner_BookInBlock!$A:$A,Partner_BookInBlock!J:J,"",0)="Free","Free",IF(XLOOKUP($A4,Partner_BookInBlock!$A:$A,Partner_BookInBlock!J:J,"",0)="VL","VL",IF(XLOOKUP($A4,Partner_BookInBlock!$A:$A,Partner_BookInBlock!J:J,"",0)="ATT","ATT",XLOOKUP($A4,Partner_BookInBlock!$A:$A,Partner_BookInBlock!J:J,"",0))))} -> 0.33333333 | K4: {=IF(XLOOKUP($A4,Partner_BookInBlock!$A:$A,Partner_BookInBlock!K:K,"",0)="Free","Free",IF(XLOOKUP($A4,Partner_BookInBlock!$A:$A,Partner_BookInBlock!K:K,"",0)="VL","VL",IF(XLOOKUP($A4,Partner_BookInBlock!$A:$A,Partner_BookInBlock!K:K,"",0)="ATT","ATT",XLOOKUP($A4,Partner_BookInBlock!$A:$A,Partner_BookInBlock!K:K,"",0))))} | L4: {=IF(XLOOKUP($A4,Partner_BookInBlock!$A:$A,Partner_BookInBlock!L:L,"",0)="Free","Free",IF(XLOOKUP($A4,Partner_BookInBlock!$A:$A,Partner_BookInBlock!L:L,"",0)="VL","VL",IF(XLOOKUP($A4,Partner_BookInBlock!$A:$A,Partner_BookInBlock!L:L,"",0)="ATT","ATT",XLOOKUP($A4,Partner_BookInBlock!$A:$A,Partner_BookInBlock!L:L,"",0))))} -> 0.33333333 | M4: {=IF(XLOOKUP($A4,Partner_BookInBlock!$A:$A,Partner_BookInBlock!M:M,"",0)="Free","Free",IF(XLOOKUP($A4,Partner_BookInBlock!$A:$A,Partner_BookInBlock!M:M,"",0)="VL","VL",IF(XLOOKUP($A4,Partner_BookInBlock!$A:$A,Partner_BookInBlock!M:M,"",0)="ATT","ATT",XLOOKUP($A4,Partner_BookInBlock!$A:$A,Partner_BookInBlock!M:M,"",0))))} -> 0.33333333 | N4: {=IF(XLOOKUP($A4,Partner_BookInBlock!$A:$A,Partner_BookInBlock!N:N,"",0)="Free","Free",IF(XLOOKUP($A4,Partner_BookInBlock!$A:$A,Partner_BookInBlock!N:N,"",0)="VL","VL",IF(XLOOKUP($A4,Partner_BookInBlock!$A:$A,Partner_BookInBlock!N:N,"",0)="ATT","ATT",XLOOKUP($A4,Partner_BookInBlock!$A:$A,Partner_BookInBlock!N:N,"",0))))} -> 0.33333333 | O4: {=IF(XLOOKUP($A4,Partner_BookInBlock!$A:$A,Partner_BookInBlock!O:O,"",0)="Free","Free",IF(XLOOKUP($A4,Partner_BookInBlock!$A:$A,Partner_BookInBlock!O:O,"",0)="VL","VL",IF(XLOOKUP($A4,Partner_BookInBlock!$A:$A,Partner_BookInBlock!O:O,"",0)="ATT","ATT",XLOOKUP($A4,Partner_BookInBlock!$A:$A,Partner_BookInBlock!O:O,"",0))))} -> 0.33333333 | P4: {=IF(XLOOKUP($A4,Partner_BookInBlock!$A:$A,Partner_BookInBlock!P:P,"",0)="Free","Free",IF(XLOOKUP($A4,Partner_BookInBlock!$A:$A,Partner_BookInBlock!P:P,"",0)="VL","VL",IF(XLOOKUP($A4,Partner_BookInBlock!$A:$A,Partner_BookInBlock!P:P,"",0)="ATT","ATT",XLOOKUP($A4,Partner_BookInBlock!$A:$A,Partner_BookInBlock!P:P,"",0))))} -> 0.33333333 | Q4: {=IF(XLOOKUP($A4,Partner_BookInBlock!$A:$A,Partner_BookInBlock!Q:Q,"",0)="Free","Free",IF(XLOOKUP($A4,Partner_BookInBlock!$A:$A,Partner_BookInBlock!Q:Q,"",0)="VL","VL",IF(XLOOKUP($A4,Partner_BookInBlock!$A:$A,Partner_BookInBlock!Q:Q,"",0)="ATT","ATT",XLOOKUP($A4,Partner_BookInBlock!$A:$A,Partner_BookInBlock!Q:Q,"",0))))} -> Free | S4: {=IF(XLOOKUP($A4,Partner_BookInBlock!$A:$A,Partner_BookInBlock!S:S,"",0)="Free","Free",IF(XLOOKUP($A4,Partner_BookInBlock!$A:$A,Partner_BookInBlock!S:S,"",0)="VL","VL",IF(XLOOKUP($A4,Partner_BookInBlock!$A:$A,Partner_BookInBlock!S:S,"",0)="ATT","ATT",XLOOKUP($A4,Partner_BookInBlock!$A:$A,Partner_BookInBlock!S:S,"",0))))} -> 0.33333333 | T4: {=IF(XLOOKUP($A4,Partner_BookInBlock!$A:$A,Partner_BookInBlock!T:T,"",0)="Free","Free",IF(XLOOKUP($A4,Partner_BookInBlock!$A:$A,Partner_BookInBlock!T:T,"",0)="VL","VL",IF(XLOOKUP($A4,Partner_BookInBlock!$A:$A,Partner_BookInBlock!T:T,"",0)="ATT","ATT",XLOOKUP($A4,Partner_BookInBlock!$A:$A,Partner_BookInBlock!T:T,"",0))))} -> 0.33333333 | U4: {=IF(XLOOKUP($A4,Partner_BookInBlock!$A:$A,Partner_BookInBlock!U:U,"",0)="Free","Free",IF(XLOOKUP($A4,Partner_BookInBlock!$A:$A,Partner_BookInBlock!U:U,"",0)="VL","VL",IF(XLOOKUP($A4,Partner_BookInBlock!$A:$A,Partner_BookInBlock!U:U,"",0)="ATT","ATT",XLOOKUP($A4,Partner_BookInBlock!$A:$A,Partner_BookInBlock!U:U,"",0))))} -> 0.33333333 | V4: {=IF(XLOOKUP($A4,Partner_BookInBlock!$A:$A,Partner_BookInBlock!V:V,"",0)="Free","Free",IF(XLOOKUP($A4,Partner_BookInBlock!$A:$A,Partner_BookInBlock!V:V,"",0)="VL","VL",IF(XLOOKUP($A4,Partner_BookInBlock!$A:$A,Partner_BookInBlock!V:V,"",0)="ATT","ATT",XLOOKUP($A4,Partner_BookInBlock!$A:$A,Partner_BookInBlock!V:V,"",0))))} -> 0.33333333 | W4: {=IF(XLOOKUP($A4,Partner_BookInBlock!$A:$A,Partner_BookInBlock!W:W,"",0)="Free","Free",IF(XLOOKUP($A4,Partner_BookInBlock!$A:$A,Partner_BookInBlock!W:W,"",0)="VL","VL",IF(XLOOKUP($A4,Partner_BookInBlock!$A:$A,Partner_BookInBlock!W:W,"",0)="ATT","ATT",XLOOKUP($A4,Partner_BookInBlock!$A:$A,Partner_BookInBlock!W:W,"",0))))} -> 0.33333333 | X4: {=IF(XLOOKUP($A4,Partner_BookInBlock!$A:$A,Partner_BookInBlock!X:X,"",0)="Free","Free",IF(XLOOKUP($A4,Partner_BookInBlock!$A:$A,Partner_BookInBlock!X:X,"",0)="VL","VL",IF(XLOOKUP($A4,Partner_BookInBlock!$A:$A,Partner_BookInBlock!X:X,"",0)="ATT","ATT",XLOOKUP($A4,Partner_BookInBlock!$A:$A,Partner_BookInBlock!X:X,"",0))))} -> Free | Z4: {=IF(XLOOKUP($A4,Partner_BookInBlock!$A:$A,Partner_BookInBlock!Z:Z,"",0)="Free","Free",IF(XLOOKUP($A4,Partner_BookInBlock!$A:$A,Partner_BookInBlock!Z:Z,"",0)="VL","VL",IF(XLOOKUP($A4,Partner_BookInBlock!$A:$A,Partner_BookInBlock!Z:Z,"",0)="ATT","ATT",XLOOKUP($A4,Partner_BookInBlock!$A:$A,Partner_BookInBlock!Z:Z,"",0))))} -> 0.33333333 | AA4: {=IF(XLOOKUP($A4,Partner_BookInBlock!$A:$A,Partner_BookInBlock!AA:AA,"",0)="Free","Free",IF(XLOOKUP($A4,Partner_BookInBlock!$A:$A,Partner_BookInBlock!AA:AA,"",0)="VL","VL",IF(XLOOKUP($A4,Partner_BookInBlock!$A:$A,Partner_BookInBlock!AA:AA,"",0)="ATT","ATT",XLOOKUP($A4,Partner_BookInBlock!$A:$A,Partner_BookInBlock!AA:AA,"",0))))} -> 0.33333333 | AB4: {=IF(XLOOKUP($A4,Partner_BookInBlock!$A:$A,Partner_BookInBlock!AB:AB,"",0)="Free","Free",IF(XLOOKUP($A4,Partner_BookInBlock!$A:$A,Partner_BookInBlock!AB:AB,"",0)="VL","VL",IF(XLOOKUP($A4,Partner_BookInBlock!$A:$A,Partner_BookInBlock!AB:AB,"",0)="ATT","ATT",XLOOKUP($A4,Partner_BookInBlock!$A:$A,Partner_BookInBlock!AB:AB,"",0))))} -> 0.33333333 | AC4: {=IF(XLOOKUP($A4,Partner_BookInBlock!$A:$A,Partner_BookInBlock!AC:AC,"",0)="Free","Free",IF(XLOOKUP($A4,Partner_BookInBlock!$A:$A,Partner_BookInBlock!AC:AC,"",0)="VL","VL",IF(XLOOKUP($A4,Partner_BookInBlock!$A:$A,Partner_BookInBlock!AC:AC,"",0)="ATT","ATT",XLOOKUP($A4,Partner_BookInBlock!$A:$A,Partner_BookInBlock!AC:AC,"",0))))} -> 0.33333333 | AD4: {=IF(XLOOKUP($A4,Partner_BookInBlock!$A:$A,Partner_BookInBlock!AD:AD,"",0)="Free","Free",IF(XLOOKUP($A4,Partner_BookInBlock!$A:$A,Partner_BookInBlock!AD:AD,"",0)="VL","VL",IF(XLOOKUP($A4,Partner_BookInBlock!$A:$A,Partner_BookInBlock!AD:AD,"",0)="ATT","ATT",XLOOKUP($A4,Partner_BookInBlock!$A:$A,Partner_BookInBlock!AD:AD,"",0))))} -> 0.33333333 | AE4: {=IF(XLOOKUP($A4,Partner_BookInBlock!$A:$A,Partner_BookInBlock!AE:AE,"",0)="Free","Free",IF(XLOOKUP($A4,Partner_BookInBlock!$A:$A,Partner_BookInBlock!AE:AE,"",0)="VL","VL",IF(XLOOKUP($A4,Partner_BookInBlock!$A:$A,Partner_BookInBlock!AE:AE,"",0)="ATT","ATT",XLOOKUP($A4,Partner_BookInBlock!$A:$A,Partner_BookInBlock!AE:AE,"",0))))} -> Free | AG4: {=IF(XLOOKUP($A4,Partner_BookInBlock!$A:$A,Partner_BookInBlock!AG:AG,"",0)="Free","Free",IF(XLOOKUP($A4,Partner_BookInBlock!$A:$A,Partner_BookInBlock!AG:AG,"",0)="VL","VL",IF(XLOOKUP($A4,Partner_BookInBlock!$A:$A,Partner_BookInBlock!AG:AG,"",0)="ATT","ATT",XLOOKUP($A4,Partner_BookInBlock!$A:$A,Partner_BookInBlock!AG:AG,"",0))))} -> 0.33333333 | AH4: {=IF(XLOOKUP($A4,Partner_BookInBlock!$A:$A,Partner_BookInBlock!AH:AH,"",0)="Free","Free",IF(XLOOKUP($A4,Partner_BookInBlock!$A:$A,Partner_BookInBlock!AH:AH,"",0)="VL","VL",IF(XLOOKUP($A4,Partner_BookInBlock!$A:$A,Partner_BookInBlock!AH:AH,"",0)="ATT","ATT",XLOOKUP($A4,Partner_BookInBlock!$A:$A,Partner_BookInBlock!AH:AH,"",0))))} -> 0.33333333 | AI4: {=IF(XLOOKUP($A4,Partner_BookInBlock!$A:$A,Partner_BookInBlock!AI:AI,"",0)="Free","Free",IF(XLOOKUP($A4,Partner_BookInBlock!$A:$A,Partner_BookInBlock!AI:AI,"",0)="VL","VL",IF(XLOOKUP($A4,Partner_BookInBlock!$A:$A,Partner_BookInBlock!AI:AI,"",0)="ATT","ATT",XLOOKUP($A4,Partner_BookInBlock!$A:$A,Partner_BookInBlock!AI:AI,"",0))))} -> 0.33333333 | AJ4: {=IF(XLOOKUP($A4,Partner_BookInBlock!$A:$A,Partner_BookInBlock!AJ:AJ,"",0)="Free","Free",IF(XLOOKUP($A4,Partner_BookInBlock!$A:$A,Partner_BookInBlock!AJ:AJ,"",0)="VL","VL",IF(XLOOKUP($A4,Partner_BookInBlock!$A:$A,Partner_BookInBlock!AJ:AJ,"",0)="ATT","ATT",XLOOKUP($A4,Partner_BookInBlock!$A:$A,Partner_BookInBlock!AJ:AJ,"",0))))} -> 0.33333333 | AK4: {=IF(XLOOKUP($A4,Partner_BookInBlock!$A:$A,Partner_BookInBlock!AK:AK,"",0)="Free","Free",IF(XLOOKUP($A4,Partner_BookInBlock!$A:$A,Partner_BookInBlock!AK:AK,"",0)="VL","VL",IF(XLOOKUP($A4,Partner_BookInBlock!$A:$A,Partner_BookInBlock!AK:AK,"",0)="ATT","ATT",XLOOKUP($A4,Partner_BookInBlock!$A:$A,Partner_BookInBlock!AK:AK,"",0))))} -> 0.33333333 | AL4: {=IF(XLOOKUP($A4,Partner_BookInBlock!$A:$A,Partner_BookInBlock!AL:AL,"",0)="Free","Free",IF(XLOOKUP($A4,Partner_BookInBlock!$A:$A,Partner_BookInBlock!AL:AL,"",0)="VL","VL",IF(XLOOKUP($A4,Partner_BookInBlock!$A:$A,Partner_BookInBlock!AL:AL,"",0)="ATT","ATT",XLOOKUP($A4,Partner_BookInBlock!$A:$A,Partner_BookInBlock!AL:AL,"",0))))} -> Free
A5: C699 | B5: {=XLOOKUP(A5,Roster!F:F,Roster!A:A,"",0)} -> Bryan Galvis | C5: {=XLOOKUP(A5,Roster!F:F,Roster!B:B,"",0)} -> Alexa Arenas | E5: {=IF(XLOOKUP($A5,Partner_Tickets!$A:$A,Partner_Tickets!E:E,"",0)="Free","Free",IF(XLOOKUP($A5,Partner_Tickets!$A:$A,Partner_Tickets!E:E,"",0)="VL","VL",IF(XLOOKUP($A5,Partner_Tickets!$A:$A,Partner_Tickets!E:E,"",0)="ATT","ATT",XLOOKUP($A5,Partner_Tickets!$A:$A,Partner_Tickets!E:E,"",0))))} -> 0.33333333 | F5: {=IF(XLOOKUP($A5,Partner_Tickets!$A:$A,Partner_Tickets!F:F,"",0)="Free","Free",IF(XLOOKUP($A5,Partner_Tickets!$A:$A,Partner_Tickets!F:F,"",0)="VL","VL",IF(XLOOKUP($A5,Partner_Tickets!$A:$A,Partner_Tickets!F:F,"",0)="ATT","ATT",XLOOKUP($A5,Partner_Tickets!$A:$A,Partner_Tickets!F:F,"",0))))} -> 0.33333333 | G5: {=IF(XLOOKUP($A5,Partner_Tickets!$A:$A,Partner_Tickets!G:G,"",0)="Free","Free",IF(XLOOKUP($A5,Partner_Tickets!$A:$A,Partner_Tickets!G:G,"",0)="VL","VL",IF(XLOOKUP($A5,Partner_Tickets!$A:$A,Partner_Tickets!G:G,"",0)="ATT","ATT",XLOOKUP($A5,Partner_Tickets!$A:$A,Partner_Tickets!G:G,"",0))))} -> 0.33333333 | H5: {=IF(XLOOKUP($A5,Partner_Tickets!$A:$A,Partner_Tickets!H:H,"",0)="Free","Free",IF(XLOOKUP($A5,Partner_Tickets!$A:$A,Partner_Tickets!H:H,"",0)="VL","VL",IF(XLOOKUP($A5,Partner_Tickets!$A:$A,Partner_Tickets!H:H,"",0)="ATT","ATT",XLOOKUP($A5,Partner_Tickets!$A:$A,Partner_Tickets!H:H,"",0))))} -> 0.33333333 | I5: {=IF(XLOOKUP($A5,Partner_Tickets!$A:$A,Partner_Tickets!I:I,"",0)="Free","Free",IF(XLOOKUP($A5,Partner_Tickets!$A:$A,Partner_Tickets!I:I,"",0)="VL","VL",IF(XLOOKUP($A5,Partner_Tickets!$A:$A,Partner_Tickets!I:I,"",0)="ATT","ATT",XLOOKUP($A5,Partner_Tickets!$A:$A,Partner_Tickets!I:I,"",0))))} -> 0.33333333 | J5: {=IF(XLOOKUP($A5,Partner_Tickets!$A:$A,Partner_Tickets!J:J,"",0)="Free","Free",IF(XLOOKUP($A5,Partner_Tickets!$A:$A,Partner_Tickets!J:J,"",0)="VL","VL",IF(XLOOKUP($A5,Partner_Tickets!$A:$A,Partner_Tickets!J:J,"",0)="ATT","ATT",XLOOKUP($A5,Partner_Tickets!$A:$A,Partner_Tickets!J:J,"",0))))} -> Free | K5: {=IF(XLOOKUP($A5,Partner_Tickets!$A:$A,Partner_Tickets!K:K,"",0)="Free","Free",IF(XLOOKUP($A5,Partner_Tickets!$A:$A,Partner_Tickets!K:K,"",0)="VL","VL",IF(XLOOKUP($A5,Partner_Tickets!$A:$A,Partner_Tickets!K:K,"",0)="ATT","ATT",XLOOKUP($A5,Partner_Tickets!$A:$A,Partner_Tickets!K:K,"",0))))} | L5: {=IF(XLOOKUP($A5,Partner_Tickets!$A:$A,Partner_Tickets!L:L,"",0)="Free","Free",IF(XLOOKUP($A5,Partner_Tickets!$A:$A,Partner_Tickets!L:L,"",0)="VL","VL",IF(XLOOKUP($A5,Partner_Tickets!$A:$A,Partner_Tickets!L:L,"",0)="ATT","ATT",XLOOKUP($A5,Partner_Tickets!$A:$A,Partner_Tickets!L:L,"",0))))} -> 0.33333333 | M5: {=IF(XLOOKUP($A5,Partner_Tickets!$A:$A,Partner_Tickets!M:M,"",0)="Free","Free",IF(XLOOKUP($A5,Partner_Tickets!$A:$A,Partner_Tickets!M:M,"",0)="VL","VL",IF(XLOOKUP($A5,Partner_Tickets!$A:$A,Partner_Tickets!M:M,"",0)="ATT","ATT",XLOOKUP($A5,Partner_Tickets!$A:$A,Partner_Tickets!M:M,"",0))))} -> 0.33333333 | N5: {=IF(XLOOKUP($A5,Partner_Tickets!$A:$A,Partner_Tickets!N:N,"",0)="Free","Free",IF(XLOOKUP($A5,Partner_Tickets!$A:$A,Partner_Tickets!N:N,"",0)="VL","VL",IF(XLOOKUP($A5,Partner_Tickets!$A:$A,Partner_Tickets!N:N,"",0)="ATT","ATT",XLOOKUP($A5,Partner_Tickets!$A:$A,Partner_Tickets!N:N,"",0))))} -> 0.33333333 | O5: {=IF(XLOOKUP($A5,Partner_Tickets!$A:$A,Partner_Tickets!O:O,"",0)="Free","Free",IF(XLOOKUP($A5,Partner_Tickets!$A:$A,Partner_Tickets!O:O,"",0)="VL","VL",IF(XLOOKUP($A5,Partner_Tickets!$A:$A,Partner_Tickets!O:O,"",0)="ATT","ATT",XLOOKUP($A5,Partner_Tickets!$A:$A,Partner_Tickets!O:O,"",0))))} -> 0.33333333 | P5: {=IF(XLOOKUP($A5,Partner_Tickets!$A:$A,Partner_Tickets!P:P,"",0)="Free","Free",IF(XLOOKUP($A5,Partner_Tickets!$A:$A,Partner_Tickets!P:P,"",0)="VL","VL",IF(XLOOKUP($A5,Partner_Tickets!$A:$A,Partner_Tickets!P:P,"",0)="ATT","ATT",XLOOKUP($A5,Partner_Tickets!$A:$A,Partner_Tickets!P:P,"",0))))} -> 0.33333333 | Q5: {=IF(XLOOKUP($A5,Partner_Tickets!$A:$A,Partner_Tickets!Q:Q,"",0)="Free","Free",IF(XLOOKUP($A5,Partner_Tickets!$A:$A,Partner_Tickets!Q:Q,"",0)="VL","VL",IF(XLOOKUP($A5,Partner_Tickets!$A:$A,Partner_Tickets!Q:Q,"",0)="ATT","ATT",XLOOKUP($A5,Partner_Tickets!$A:$A,Partner_Tickets!Q:Q,"",0))))} -> Free | S5: {=IF(XLOOKUP($A5,Partner_Tickets!$A:$A,Partner_Tickets!S:S,"",0)="Free","Free",IF(XLOOKUP($A5,Partner_Tickets!$A:$A,Partner_Tickets!S:S,"",0)="VL","VL",IF(XLOOKUP($A5,Partner_Tickets!$A:$A,Partner_Tickets!S:S,"",0)="ATT","ATT",XLOOKUP($A5,Partner_Tickets!$A:$A,Partner_Tickets!S:S,"",0))))} -> 0.33333333 | T5: {=IF(XLOOKUP($A5,Partner_Tickets!$A:$A,Partner_Tickets!T:T,"",0)="Free","Free",IF(XLOOKUP($A5,Partner_Tickets!$A:$A,Partner_Tickets!T:T,"",0)="VL","VL",IF(XLOOKUP($A5,Partner_Tickets!$A:$A,Partner_Tickets!T:T,"",0)="ATT","ATT",XLOOKUP($A5,Partner_Tickets!$A:$A,Partner_Tickets!T:T,"",0))))} -> 0.33333333 | U5: {=IF(XLOOKUP($A5,Partner_Tickets!$A:$A,Partner_Tickets!U:U,"",0)="Free","Free",IF(XLOOKUP($A5,Partner_Tickets!$A:$A,Partner_Tickets!U:U,"",0)="VL","VL",IF(XLOOKUP($A5,Partner_Tickets!$A:$A,Partner_Tickets!U:U,"",0)="ATT","ATT",XLOOKUP($A5,Partner_Tickets!$A:$A,Partner_Tickets!U:U,"",0))))} -> 0.33333333 | V5: {=IF(XLOOKUP($A5,Partner_Tickets!$A:$A,Partner_Tickets!V:V,"",0)="Free","Free",IF(XLOOKUP($A5,Partner_Tickets!$A:$A,Partner_Tickets!V:V,"",0)="VL","VL",IF(XLOOKUP($A5,Partner_Tickets!$A:$A,Partner_Tickets!V:V,"",0)="ATT","ATT",XLOOKUP($A5,Partner_Tickets!$A:$A,Partner_Tickets!V:V,"",0))))} -> 0.33333333 | W5: {=IF(XLOOKUP($A5,Partner_Tickets!$A:$A,Partner_Tickets!W:W,"",0)="Free","Free",IF(XLOOKUP($A5,Partner_Tickets!$A:$A,Partner_Tickets!W:W,"",0)="VL","VL",IF(XLOOKUP($A5,Partner_Tickets!$A:$A,Partner_Tickets!W:W,"",0)="ATT","ATT",XLOOKUP($A5,Partner_Tickets!$A:$A,Partner_Tickets!W:W,"",0))))} -> 0.33333333 | X5: {=IF(XLOOKUP($A5,Partner_Tickets!$A:$A,Partner_Tickets!X:X,"",0)="Free","Free",IF(XLOOKUP($A5,Partner_Tickets!$A:$A,Partner_Tickets!X:X,"",0)="VL","VL",IF(XLOOKUP($A5,Partner_Tickets!$A:$A,Partner_Tickets!X:X,"",0)="ATT","ATT",XLOOKUP($A5,Partner_Tickets!$A:$A,Partner_Tickets!X:X,"",0))))} -> Free | Z5: {=IF(XLOOKUP($A5,Partner_Tickets!$A:$A,Partner_Tickets!Z:Z,"",0)="Free","Free",IF(XLOOKUP($A5,Partner_Tickets!$A:$A,Partner_Tickets!Z:Z,"",0)="VL","VL",IF(XLOOKUP($A5,Partner_Tickets!$A:$A,Partner_Tickets!Z:Z,"",0)="ATT","ATT",XLOOKUP($A5,Partner_Tickets!$A:$A,Partner_Tickets!Z:Z,"",0))))} -> 0.33333333 | AA5: {=IF(XLOOKUP($A5,Partner_Tickets!$A:$A,Partner_Tickets!AA:AA,"",0)="Free","Free",IF(XLOOKUP($A5,Partner_Tickets!$A:$A,Partner_Tickets!AA:AA,"",0)="VL","VL",IF(XLOOKUP($A5,Partner_Tickets!$A:$A,Partner_Tickets!AA:AA,"",0)="ATT","ATT",XLOOKUP($A5,Partner_Tickets!$A:$A,Partner_Tickets!AA:AA,"",0))))} -> 0.33333333 | AB5: {=IF(XLOOKUP($A5,Partner_Tickets!$A:$A,Partner_Tickets!AB:AB,"",0)="Free","Free",IF(XLOOKUP($A5,Partner_Tickets!$A:$A,Partner_Tickets!AB:AB,"",0)="VL","VL",IF(XLOOKUP($A5,Partner_Tickets!$A:$A,Partner_Tickets!AB:AB,"",0)="ATT","ATT",XLOOKUP($A5,Partner_Tickets!$A:$A,Partner_Tickets!AB:AB,"",0))))} -> 0.33333333 | AC5: {=IF(XLOOKUP($A5,Partner_Tickets!$A:$A,Partner_Tickets!AC:AC,"",0)="Free","Free",IF(XLOOKUP($A5,Partner_Tickets!$A:$A,Partner_Tickets!AC:AC,"",0)="VL","VL",IF(XLOOKUP($A5,Partner_Tickets!$A:$A,Partner_Tickets!AC:AC,"",0)="ATT","ATT",XLOOKUP($A5,Partner_Tickets!$A:$A,Partner_Tickets!AC:AC,"",0))))} -> 0.33333333 | AD5: {=IF(XLOOKUP($A5,Partner_Tickets!$A:$A,Partner_Tickets!AD:AD,"",0)="Free","Free",IF(XLOOKUP($A5,Partner_Tickets!$A:$A,Partner_Tickets!AD:AD,"",0)="VL","VL",IF(XLOOKUP($A5,Partner_Tickets!$A:$A,Partner_Tickets!AD:AD,"",0)="ATT","ATT",XLOOKUP($A5,Partner_Tickets!$A:$A,Partner_Tickets!AD:AD,"",0))))} -> 0.33333333 | AE5: {=IF(XLOOKUP($A5,Partner_Tickets!$A:$A,Partner_Tickets!AE:AE,"",0)="Free","Free",IF(XLOOKUP($A5,Partner_Tickets!$A:$A,Partner_Tickets!AE:AE,"",0)="VL","VL",IF(XLOOKUP($A5,Partner_Tickets!$A:$A,Partner_Tickets!AE:AE,"",0)="ATT","ATT",XLOOKUP($A5,Partner_Tickets!$A:$A,Partner_Tickets!AE:AE,"",0))))} -> Free | AG5: {=IF(XLOOKUP($A5,Partner_Tickets!$A:$A,Partner_Tickets!AG:AG,"",0)="Free","Free",IF(XLOOKUP($A5,Partner_Tickets!$A:$A,Partner_Tickets!AG:AG,"",0)="VL","VL",IF(XLOOKUP($A5,Partner_Tickets!$A:$A,Partner_Tickets!AG:AG,"",0)="ATT","ATT",XLOOKUP($A5,Partner_Tickets!$A:$A,Partner_Tickets!AG:AG,"",0))))} -> 0.33333333 | AH5: {=IF(XLOOKUP($A5,Partner_Tickets!$A:$A,Partner_Tickets!AH:AH,"",0)="Free","Free",IF(XLOOKUP($A5,Partner_Tickets!$A:$A,Partner_Tickets!AH:AH,"",0)="VL","VL",IF(XLOOKUP($A5,Partner_Tickets!$A:$A,Partner_Tickets!AH:AH,"",0)="ATT","ATT",XLOOKUP($A5,Partner_Tickets!$A:$A,Partner_Tickets!AH:AH,"",0))))} -> 0.33333333 | AI5: {=IF(XLOOKUP($A5,Partner_Tickets!$A:$A,Partner_Tickets!AI:AI,"",0)="Free","Free",IF(XLOOKUP($A5,Partner_Tickets!$A:$A,Partner_Tickets!AI:AI,"",0)="VL","VL",IF(XLOOKUP($A5,Partner_Tickets!$A:$A,Partner_Tickets!AI:AI,"",0)="ATT","ATT",XLOOKUP($A5,Partner_Tickets!$A:$A,Partner_Tickets!AI:AI,"",0))))} -> 0.33333333 | AJ5: {=IF(XLOOKUP($A5,Partner_Tickets!$A:$A,Partner_Tickets!AJ:AJ,"",0)="Free","Free",IF(XLOOKUP($A5,Partner_Tickets!$A:$A,Partner_Tickets!AJ:AJ,"",0)="VL","VL",IF(XLOOKUP($A5,Partner_Tickets!$A:$A,Partner_Tickets!AJ:AJ,"",0)="ATT","ATT",XLOOKUP($A5,Partner_Tickets!$A:$A,Partner_Tickets!AJ:AJ,"",0))))} -> 0.33333333 | AK5: {=IF(XLOOKUP($A5,Partner_Tickets!$A:$A,Partner_Tickets!AK:AK,"",0)="Free","Free",IF(XLOOKUP($A5,Partner_Tickets!$A:$A,Partner_Tickets!AK:AK,"",0)="VL","VL",IF(XLOOKUP($A5,Partner_Tickets!$A:$A,Partner_Tickets!AK:AK,"",0)="ATT","ATT",XLOOKUP($A5,Partner_Tickets!$A:$A,Partner_Tickets!AK:AK,"",0))))} -> 0.33333333 | AL5: {=IF(XLOOKUP($A5,Partner_Tickets!$A:$A,Partner_Tickets!AL:AL,"",0)="Free","Free",IF(XLOOKUP($A5,Partner_Tickets!$A:$A,Partner_Tickets!AL:AL,"",0)="VL","VL",IF(XLOOKUP($A5,Partner_Tickets!$A:$A,Partner_Tickets!AL:AL,"",0)="ATT","ATT",XLOOKUP($A5,Partner_Tickets!$A:$A,Partner_Tickets!AL:AL,"",0))))} -> Free
A6: C080 | B6: {=XLOOKUP(A6,Roster!F:F,Roster!A:A,"",0)} -> Bryan Galvis | C6: {=XLOOKUP(A6,Roster!F:F,Roster!B:B,"",0)} -> Arturo Padilla | E6: {=IF(XLOOKUP($A6,Partner_Tickets!$A:$A,Partner_Tickets!E:E,"",0)="Free","Free",IF(XLOOKUP($A6,Partner_Tickets!$A:$A,Partner_Tickets!E:E,"",0)="VL","VL",IF(XLOOKUP($A6,Partner_Tickets!$A:$A,Partner_Tickets!E:E,"",0)="ATT","ATT",XLOOKUP($A6,Partner_Tickets!$A:$A,Partner_Tickets!E:E,"",0))))} -> 0.33333333 | F6: {=IF(XLOOKUP($A6,Partner_Tickets!$A:$A,Partner_Tickets!F:F,"",0)="Free","Free",IF(XLOOKUP($A6,Partner_Tickets!$A:$A,Partner_Tickets!F:F,"",0)="VL","VL",IF(XLOOKUP($A6,Partner_Tickets!$A:$A,Partner_Tickets!F:F,"",0)="ATT","ATT",XLOOKUP($A6,Partner_Tickets!$A:$A,Partner_Tickets!F:F,"",0))))} -> 0.33333333 | G6: {=IF(XLOOKUP($A6,Partner_Tickets!$A:$A,Partner_Tickets!G:G,"",0)="Free","Free",IF(XLOOKUP($A6,Partner_Tickets!$A:$A,Partner_Tickets!G:G,"",0)="VL","VL",IF(XLOOKUP($A6,Partner_Tickets!$A:$A,Partner_Tickets!G:G,"",0)="ATT","ATT",XLOOKUP($A6,Partner_Tickets!$A:$A,Partner_Tickets!G:G,"",0))))} -> 0.33333333 | H6: {=IF(XLOOKUP($A6,Partner_Tickets!$A:$A,Partner_Tickets!H:H,"",0)="Free","Free",IF(XLOOKUP($A6,Partner_Tickets!$A:$A,Partner_Tickets!H:H,"",0)="VL","VL",IF(XLOOKUP($A6,Partner_Tickets!$A:$A,Partner_Tickets!H:H,"",0)="ATT","ATT",XLOOKUP($A6,Partner_Tickets!$A:$A,Partner_Tickets!H:H,"",0))))} -> 0.33333333 | I6: {=IF(XLOOKUP($A6,Partner_Tickets!$A:$A,Partner_Tickets!I:I,"",0)="Free","Free",IF(XLOOKUP($A6,Partner_Tickets!$A:$A,Partner_Tickets!I:I,"",0)="VL","VL",IF(XLOOKUP($A6,Partner_Tickets!$A:$A,Partner_Tickets!I:I,"",0)="ATT","ATT",XLOOKUP($A6,Partner_Tickets!$A:$A,Partner_Tickets!I:I,"",0))))} -> 0.33333333 | J6: {=IF(XLOOKUP($A6,Partner_Tickets!$A:$A,Partner_Tickets!J:J,"",0)="Free","Free",IF(XLOOKUP($A6,Partner_Tickets!$A:$A,Partner_Tickets!J:J,"",0)="VL","VL",IF(XLOOKUP($A6,Partner_Tickets!$A:$A,Partner_Tickets!J:J,"",0)="ATT","ATT",XLOOKUP($A6,Partner_Tickets!$A:$A,Partner_Tickets!J:J,"",0))))} -> Free | K6: {=IF(XLOOKUP($A6,Partner_Tickets!$A:$A,Partner_Tickets!K:K,"",0)="Free","Free",IF(XLOOKUP($A6,Partner_Tickets!$A:$A,Partner_Tickets!K:K,"",0)="VL","VL",IF(XLOOKUP($A6,Partner_Tickets!$A:$A,Partner_Tickets!K:K,"",0)="ATT","ATT",XLOOKUP($A6,Partner_Tickets!$A:$A,Partner_Tickets!K:K,"",0))))} | L6: {=IF(XLOOKUP($A6,Partner_Tickets!$A:$A,Partner_Tickets!L:L,"",0)="Free","Free",IF(XLOOKUP($A6,Partner_Tickets!$A:$A,Partner_Tickets!L:L,"",0)="VL","VL",IF(XLOOKUP($A6,Partner_Tickets!$A:$A,Partner_Tickets!L:L,"",0)="ATT","ATT",XLOOKUP($A6,Partner_Tickets!$A:$A,Partner_Tickets!L:L,"",0))))} -> 0.33333333 | M6: {=IF(XLOOKUP($A6,Partner_Tickets!$A:$A,Partner_Tickets!M:M,"",0)="Free","Free",IF(XLOOKUP($A6,Partner_Tickets!$A:$A,Partner_Tickets!M:M,"",0)="VL","VL",IF(XLOOKUP($A6,Partner_Tickets!$A:$A,Partner_Tickets!M:M,"",0)="ATT","ATT",XLOOKUP($A6,Partner_Tickets!$A:$A,Partner_Tickets!M:M,"",0))))} -> 0.33333333 | N6: {=IF(XLOOKUP($A6,Partner_Tickets!$A:$A,Partner_Tickets!N:N,"",0)="Free","Free",IF(XLOOKUP($A6,Partner_Tickets!$A:$A,Partner_Tickets!N:N,"",0)="VL","VL",IF(XLOOKUP($A6,Partner_Tickets!$A:$A,Partner_Tickets!N:N,"",0)="ATT","ATT",XLOOKUP($A6,Partner_Tickets!$A:$A,Partner_Tickets!N:N,"",0))))} -> 0.33333333 | O6: {=IF(XLOOKUP($A6,Partner_Tickets!$A:$A,Partner_Tickets!O:O,"",0)="Free","Free",IF(XLOOKUP($A6,Partner_Tickets!$A:$A,Partner_Tickets!O:O,"",0)="VL","VL",IF(XLOOKUP($A6,Partner_Tickets!$A:$A,Partner_Tickets!O:O,"",0)="ATT","ATT",XLOOKUP($A6,Partner_Tickets!$A:$A,Partner_Tickets!O:O,"",0))))} -> 0.33333333 | P6: {=IF(XLOOKUP($A6,Partner_Tickets!$A:$A,Partner_Tickets!P:P,"",0)="Free","Free",IF(XLOOKUP($A6,Partner_Tickets!$A:$A,Partner_Tickets!P:P,"",0)="VL","VL",IF(XLOOKUP($A6,Partner_Tickets!$A:$A,Partner_Tickets!P:P,"",0)="ATT","ATT",XLOOKUP($A6,Partner_Tickets!$A:$A,Partner_Tickets!P:P,"",0))))} -> 0.33333333 | Q6: {=IF(XLOOKUP($A6,Partner_Tickets!$A:$A,Partner_Tickets!Q:Q,"",0)="Free","Free",IF(XLOOKUP($A6,Partner_Tickets!$A:$A,Partner_Tickets!Q:Q,"",0)="VL","VL",IF(XLOOKUP($A6,Partner_Tickets!$A:$A,Partner_Tickets!Q:Q,"",0)="ATT","ATT",XLOOKUP($A6,Partner_Tickets!$A:$A,Partner_Tickets!Q:Q,"",0))))} -> Free | S6: {=IF(XLOOKUP($A6,Partner_Tickets!$A:$A,Partner_Tickets!S:S,"",0)="Free","Free",IF(XLOOKUP($A6,Partner_Tickets!$A:$A,Partner_Tickets!S:S,"",0)="VL","VL",IF(XLOOKUP($A6,Partner_Tickets!$A:$A,Partner_Tickets!S:S,"",0)="ATT","ATT",XLOOKUP($A6,Partner_Tickets!$A:$A,Partner_Tickets!S:S,"",0))))} -> 0.33333333 | T6: {=IF(XLOOKUP($A6,Partner_Tickets!$A:$A,Partner_Tickets!T:T,"",0)="Free","Free",IF(XLOOKUP($A6,Partner_Tickets!$A:$A,Partner_Tickets!T:T,"",0)="VL","VL",IF(XLOOKUP($A6,Partner_Tickets!$A:$A,Partner_Tickets!T:T,"",0)="ATT","ATT",XLOOKUP($A6,Partner_Tickets!$A:$A,Partner_Tickets!T:T,"",0))))} -> 0.33333333 | U6: {=IF(XLOOKUP($A6,Partner_Tickets!$A:$A,Partner_Tickets!U:U,"",0)="Free","Free",IF(XLOOKUP($A6,Partner_Tickets!$A:$A,Partner_Tickets!U:U,"",0)="VL","VL",IF(XLOOKUP($A6,Partner_Tickets!$A:$A,Partner_Tickets!U:U,"",0)="ATT","ATT",XLOOKUP($A6,Partner_Tickets!$A:$A,Partner_Tickets!U:U,"",0))))} -> 0.33333333 | V6: {=IF(XLOOKUP($A6,Partner_Tickets!$A:$A,Partner_Tickets!V:V,"",0)="Free","Free",IF(XLOOKUP($A6,Partner_Tickets!$A:$A,Partner_Tickets!V:V,"",0)="VL","VL",IF(XLOOKUP($A6,Partner_Tickets!$A:$A,Partner_Tickets!V:V,"",0)="ATT","ATT",XLOOKUP($A6,Partner_Tickets!$A:$A,Partner_Tickets!V:V,"",0))))} -> 0.33333333 | W6: {=IF(XLOOKUP($A6,Partner_Tickets!$A:$A,Partner_Tickets!W:W,"",0)="Free","Free",IF(XLOOKUP($A6,Partner_Tickets!$A:$A,Partner_Tickets!W:W,"",0)="VL","VL",IF(XLOOKUP($A6,Partner_Tickets!$A:$A,Partner_Tickets!W:W,"",0)="ATT","ATT",XLOOKUP($A6,Partner_Tickets!$A:$A,Partner_Tickets!W:W,"",0))))} -> 0.33333333 | X6: {=IF(XLOOKUP($A6,Partner_Tickets!$A:$A,Partner_Tickets!X:X,"",0)="Free","Free",IF(XLOOKUP($A6,Partner_Tickets!$A:$A,Partner_Tickets!X:X,"",0)="VL","VL",IF(XLOOKUP($A6,Partner_Tickets!$A:$A,Partner_Tickets!X:X,"",0)="ATT","ATT",XLOOKUP($A6,Partner_Tickets!$A:$A,Partner_Tickets!X:X,"",0))))} -> Free | Z6: {=IF(XLOOKUP($A6,Partner_Tickets!$A:$A,Partner_Tickets!Z:Z,"",0)="Free","Free",IF(XLOOKUP($A6,Partner_Tickets!$A:$A,Partner_Tickets!Z:Z,"",0)="VL","VL",IF(XLOOKUP($A6,Partner_Tickets!$A:$A,Partner_Tickets!Z:Z,"",0)="ATT","ATT",XLOOKUP($A6,Partner_Tickets!$A:$A,Partner_Tickets!Z:Z,"",0))))} -> 0.33333333 | AA6: {=IF(XLOOKUP($A6,Partner_Tickets!$A:$A,Partner_Tickets!AA:AA,"",0)="Free","Free",IF(XLOOKUP($A6,Partner_Tickets!$A:$A,Partner_Tickets!AA:AA,"",0)="VL","VL",IF(XLOOKUP($A6,Partner_Tickets!$A:$A,Partner_Tickets!AA:AA,"",0)="ATT","ATT",XLOOKUP($A6,Partner_Tickets!$A:$A,Partner_Tickets!AA:AA,"",0))))} -> 0.33333333 | AB6: {=IF(XLOOKUP($A6,Partner_Tickets!$A:$A,Partner_Tickets!AB:AB,"",0)="Free","Free",IF(XLOOKUP($A6,Partner_Tickets!$A:$A,Partner_Tickets!AB:AB,"",0)="VL","VL",IF(XLOOKUP($A6,Partner_Tickets!$A:$A,Partner_Tickets!AB:AB,"",0)="ATT","ATT",XLOOKUP($A6,Partner_Tickets!$A:$A,Partner_Tickets!AB:AB,"",0))))} -> 0.33333333 | AC6: {=IF(XLOOKUP($A6,Partner_Tickets!$A:$A,Partner_Tickets!AC:AC,"",0)="Free","Free",IF(XLOOKUP($A6,Partner_Tickets!$A:$A,Partner_Tickets!AC:AC,"",0)="VL","VL",IF(XLOOKUP($A6,Partner_Tickets!$A:$A,Partner_Tickets!AC:AC,"",0)="ATT","ATT",XLOOKUP($A6,Partner_Tickets!$A:$A,Partner_Tickets!AC:AC,"",0))))} -> 0.33333333 | AD6: {=IF(XLOOKUP($A6,Partner_Tickets!$A:$A,Partner_Tickets!AD:AD,"",0)="Free","Free",IF(XLOOKUP($A6,Partner_Tickets!$A:$A,Partner_Tickets!AD:AD,"",0)="VL","VL",IF(XLOOKUP($A6,Partner_Tickets!$A:$A,Partner_Tickets!AD:AD,"",0)="ATT","ATT",XLOOKUP($A6,Partner_Tickets!$A:$A,Partner_Tickets!AD:AD,"",0))))} -> 0.33333333 | AE6: {=IF(XLOOKUP($A6,Partner_Tickets!$A:$A,Partner_Tickets!AE:AE,"",0)="Free","Free",IF(XLOOKUP($A6,Partner_Tickets!$A:$A,Partner_Tickets!AE:AE,"",0)="VL","VL",IF(XLOOKUP($A6,Partner_Tickets!$A:$A,Partner_Tickets!AE:AE,"",0)="ATT","ATT",XLOOKUP($A6,Partner_Tickets!$A:$A,Partner_Tickets!AE:AE,"",0))))} -> Free | AG6: {=IF(XLOOKUP($A6,Partner_Tickets!$A:$A,Partner_Tickets!AG:AG,"",0)="Free","Free",IF(XLOOKUP($A6,Partner_Tickets!$A:$A,Partner_Tickets!AG:AG,"",0)="VL","VL",IF(XLOOKUP($A6,Partner_Tickets!$A:$A,Partner_Tickets!AG:AG,"",0)="ATT","ATT",XLOOKUP($A6,Partner_Tickets!$A:$A,Partner_Tickets!AG:AG,"",0))))} -> 0.33333333 | AH6: {=IF(XLOOKUP($A6,Partner_Tickets!$A:$A,Partner_Tickets!AH:AH,"",0)="Free","Free",IF(XLOOKUP($A6,Partner_Tickets!$A:$A,Partner_Tickets!AH:AH,"",0)="VL","VL",IF(XLOOKUP($A6,Partner_Tickets!$A:$A,Partner_Tickets!AH:AH,"",0)="ATT","ATT",XLOOKUP($A6,Partner_Tickets!$A:$A,Partner_Tickets!AH:AH,"",0))))} -> 0.33333333 | AI6: {=IF(XLOOKUP($A6,Partner_Tickets!$A:$A,Partner_Tickets!AI:AI,"",0)="Free","Free",IF(XLOOKUP($A6,Partner_Tickets!$A:$A,Partner_Tickets!AI:AI,"",0)="VL","VL",IF(XLOOKUP($A6,Partner_Tickets!$A:$A,Partner_Tickets!AI:AI,"",0)="ATT","ATT",XLOOKUP($A6,Partner_Tickets!$A:$A,Partner_Tickets!AI:AI,"",0))))} -> 0.33333333 | AJ6: {=IF(XLOOKUP($A6,Partner_Tickets!$A:$A,Partner_Tickets!AJ:AJ,"",0)="Free","Free",IF(XLOOKUP($A6,Partner_Tickets!$A:$A,Partner_Tickets!AJ:AJ,"",0)="VL","VL",IF(XLOOKUP($A6,Partner_Tickets!$A:$A,Partner_Tickets!AJ:AJ,"",0)="ATT","ATT",XLOOKUP($A6,Partner_Tickets!$A:$A,Partner_Tickets!AJ:AJ,"",0))))} -> 0.33333333 | AK6: {=IF(XLOOKUP($A6,Partner_Tickets!$A:$A,Partner_Tickets!AK:AK,"",0)="Free","Free",IF(XLOOKUP($A6,Partner_Tickets!$A:$A,Partner_Tickets!AK:AK,"",0)="VL","VL",IF(XLOOKUP($A6,Partner_Tickets!$A:$A,Partner_Tickets!AK:AK,"",0)="ATT","ATT",XLOOKUP($A6,Partner_Tickets!$A:$A,Partner_Tickets!AK:AK,"",0))))} -> 0.33333333 | AL6: {=IF(XLOOKUP($A6,Partner_Tickets!$A:$A,Partner_Tickets!AL:AL,"",0)="Free","Free",IF(XLOOKUP($A6,Partner_Tickets!$A:$A,Partner_Tickets!AL:AL,"",0)="VL","VL",IF(XLOOKUP($A6,Partner_Tickets!$A:$A,Partner_Tickets!AL:AL,"",0)="ATT","ATT",XLOOKUP($A6,Partner_Tickets!$A:$A,Partner_Tickets!AL:AL,"",0))))} -> Free
