Workbook

Sheet Masterlist
A1: UID | B1: NAME | C1: UID | D1: Team Manager | E1: Task / Position
A2: 426497 | B2: Jackielyn,Cabanas,Faro | C2: 426497 | D2: Antonette Jean Almasol | E2: Ticket Agent
A3: 264907 | B3: Lanie,Cabrera,Ramos | C3: 264907 | D3: Emmanuel Alisbo | E3: Ticket Agent
A4: 394738 | B4: Cyglen Ann Casquejo | C4: 394738 | D4: - | E4: -
A5: 388996 | B5: Jelyn Zarate | C5: 388996 | D5: Klarisse Jane Hornada | E5: Ticket Agent
A6: 388588 | B6: Danissa Bautista | C6: 388588 | D6: - | E6: -
A7: 426719 | B7: Karen,Ganit,Orbigoso | C7: 426719 | D7: - | E7: -
A8: 318217 | B8: Jose Glory Mark,Rodrigo,Calopez | C8: 318217 | D8: - | E8: -
A9: 380240 | B9: Mark Gil Apil Villagracia | C9: 380240 | D9: Klarisse Jane Hornada | E9: Ticket Agent
A10: 380214 | B10: Romel,Concepcion,Resente | C10: 380214 | D10: Klarisse Jane Hornada | E10: Ticket Agent
A11: 328974 | B11: Jean Rose,Garque,Malan | C11: 328974 | D11: - | E11: -
A12: 333053 | B12: Frank Lina,Sey,Ituriaga | C12: 333053 | D12: Klarisse Jane Hornada | E12: Ticket Agent
A13: 317122 | B13: Verlyn Rose,Aurora,Villaram | C13: 317122 | D13: Klarisse Jane Hornada | E13: Ticket Agent
... A322: 524592 | B322: Ana Marie Albao | C322: 524592 | D322: - | E322: Voice / Agent

Sheet Agent Sched
A1: Schedule (EST) | C1: WEEK BEGINNING 0427 | J1: WEEK BEGINNING 0504 | Q1: WEEK BEGINNING 0511 | Y1: Prev Sun
A2: UID | B2: Agent Name | C2: Mon | D2: Tue | E2: Wed | F2: Thu | G2: Fri | H2: Sat | I2: Sun | J2: Mon | K2: Tue | L2: Wed | M2: Thu | N2: Fri | O2: Sat | P2: Sun | Q2: Mon | R2: Tue | S2: Wed | T2: Thu | U2: Fri | V2: Sat | W2: Sun | X2: Shift | Y2: Sun | AA2: Total | AB2: =SUM(AB4:AB17) -> 50
C3: 46139 | D3: =C3+1 -> 46140 | E3: =D3+1 -> 46141 | F3: =E3+1 -> 46142 | G3: =F3+1 -> 46143 | H3: =G3+1 -> 46144 | I3: =H3+1 -> 46145 | J3: =I3+1 -> 46146 | K3: =J3+1 -> 46147 | ... W3: =V3+1 -> 46159 | Y3: =C3-1 -> 46138
A4: =VLOOKUP(B4,Masterlist!B:E,2,) -> 486925 | B4: Shenna Mae Pudadera | C4: 0.375 | D4: 0.375 | E4: 0.375 | F4: OFF | G4: OFF | H4: 0.375 | I4: 0.375 | J4: OFF | K4: 0.375 | L4: 0.375 | M4: 0.375 | N4: 0.375 | O4: 0.375 | P4: OFF | Q4: OFF | R4: 0.375 | S4: 0.375 | T4: 0.375 | U4: 0.375 | V4: 0.375 | W4: OFF | X4: =IFERROR(MODE(J4:P4),"OFF") -> 0.375 | Y4: 0.375 | AA4: 0.875 | AB4: =COUNTIF($X$4:$X$58,AA4) -> 0
A5: =VLOOKUP(B5,Masterlist!B:E,2,) -> 482673 | B5: Riva Joy Orario | C5: 0.375 | D5: 0.375 | E5: 0.375 | F5: OFF | G5: OFF | H5: 0.375 | I5: 0.375 | J5: OFF | K5: 0.375 | L5: 0.375 | M5: 0.375 | N5: 0.375 | O5: 0.375 | P5: OFF | Q5: OFF | R5: 0.375 | S5: 0.375 | T5: 0.375 | U5: 0.375 | V5: 0.375 | W5: OFF | X5: =IFERROR(MODE(J5:P5),"OFF") -> 0.375 | Y5: 0.375 | AA5: 0.5 | AB5: =COUNTIF($X$4:$X$58,AA5) -> 12
A6: =VLOOKUP(B6,Masterlist!B:E,2,) -> 417932 | B6: Eliza Grace Cortez | C6: 0.375 | D6: 0.375 | E6: 0.375 | F6: OFF | G6: OFF | H6: 0.375 | I6: 0.375 | J6: OFF | K6: 0.375 | L6: 0.375 | M6: 0.375 | N6: 0.375 | O6: 0.375 | P6: OFF | Q6: OFF | R6: 0.375 | S6: 0.375 | T6: 0.375 | U6: 0.375 | V6: 0.375 | W6: OFF | X6: =IFERROR(MODE(J6:P6),"OFF") -> 0.375 | Y6: 0.375 | AA6: 0.66666667 | AB6: =COUNTIF($X$4:$X$58,AA6) -> 0
A7: =VLOOKUP(B7,Masterlist!B:E,2,) -> 335234 | B7: Emmanuel Togle | C7: 0.375 | D7: 0.375 | E7: 0.375 | F7: OFF | G7: OFF | H7: 0.375 | I7: 0.375 | J7: OFF | K7: 0.375 | L7: 0.375 | M7: 0.375 | N7: 0.375 | O7: 0.375 | P7: OFF | Q7: OFF | R7: 0.375 | S7: 0.375 | T7: 0.375 | U7: 0.375 | V7: 0.375 | W7: OFF | X7: =IFERROR(MODE(J7:P7),"OFF") -> 0.375 | Y7: 0.375 | AA7: 0.625 | AB7: =COUNTIF($X$4:$X$58,AA7) -> 0
A8: =VLOOKUP(B8,Masterlist!B:E,2,) -> 486780 | B8: Tommy Harold Jamandron | C8: 0.375 | D8: 0.375 | E8: 0.375 | F8: OFF | G8: OFF | H8: 0.375 | I8: 0.375 | J8: OFF | K8: 0.375 | L8: 0.375 | M8: 0.375 | N8: 0.375 | O8: 0.375 | P8: OFF | Q8: OFF | R8: 0.375 | S8: 0.375 | T8: 0.375 | U8: 0.375 | V8: 0.375 | W8: OFF | X8: =IFERROR(MODE(J8:P8),"OFF") -> 0.375 | Y8: 0.375 | AA8: 0.375 | AB8: =COUNTIF($X$4:$X$133,AA8) -> 38
A9: =VLOOKUP(B9,Masterlist!B:E,2,) -> 487064 | B9: Yron Angelo Llanda | C9: 0.375 | D9: 0.375 | E9: 0.375 | F9: OFF | G9: OFF | H9: 0.375 | I9: 0.375 | J9: OFF | K9: 0.375 | L9: 0.375 | M9: 0.375 | N9: 0.375 | O9: 0.375 | P9: OFF | Q9: OFF | R9: 0.375 | S9: 0.375 | T9: 0.375 | U9: 0.375 | V9: 0.375 | W9: OFF | X9: =IFERROR(MODE(J9:P9),"OFF") -> 0.375 | Y9: 0.375
A10: =VLOOKUP(B10,Masterlist!B:E,2,) -> 379325 | B10: Annje,Libo-on,Jardinaso | C10: 0.375 | D10: 0.375 | E10: 0.375 | F10: OFF | G10: OFF | H10: 0.375 | I10: 0.375 | J10: OFF | K10: 0.375 | L10: 0.375 | M10: 0.375 | N10: 0.375 | O10: 0.375 | P10: OFF | Q10: OFF | R10: 0.375 | S10: 0.375 | T10: 0.375 | U10: 0.375 | V10: 0.375 | W10: OFF | X10: =IFERROR(MODE(J10:P10),"OFF") -> 0.375 | Y10: 0.375
A11: =VLOOKUP(B11,Masterlist!B:E,2,) -> 486897 | B11: Jovito Gadian | C11: 0.375 | D11: 0.375 | E11: 0.375 | F11: OFF | G11: OFF | H11: 0.375 | I11: 0.375 | J11: OFF | K11: 0.375 | L11: 0.375 | M11: 0.375 | N11: 0.375 | O11: 0.375 | P11: OFF | Q11: OFF | R11: 0.375 | S11: 0.375 | T11: 0.375 | U11: 0.375 | V11: 0.375 | W11: OFF | X11: =IFERROR(MODE(J11:P11),"OFF") -> 0.375 | Y11: 0.375
A12: =VLOOKUP(B12,Masterlist!B:E,2,) -> 486783 | B12: Trisha Ann Japitana | C12: 0.375 | D12: 0.375 | E12: 0.375 | F12: OFF | G12: OFF | H12: 0.375 | I12: 0.375 | J12: OFF | K12: 0.375 | L12: 0.375 | M12: 0.375 | N12: 0.375 | O12: 0.375 | P12: OFF | Q12: OFF | R12: 0.375 | S12: 0.375 | T12: 0.375 | U12: 0.375 | V12: 0.375 | W12: OFF | X12: =IFERROR(MODE(J12:P12),"OFF") -> 0.375 | Y12: 0.375
A13: =VLOOKUP(B13,Masterlist!B:E,2,) -> 482674 | B13: Reslyn Candao | C13: 0.375 | D13: 0.375 | E13: 0.375 | F13: OFF | G13: OFF | H13: 0.375 | I13: 0.375 | J13: OFF | K13: 0.375 | L13: 0.375 | M13: 0.375 | N13: 0.375 | O13: 0.375 | P13: OFF | Q13: OFF | R13: 0.375 | S13: 0.375 | T13: 0.375 | U13: 0.375 | V13: 0.375 | W13: OFF | X13: =IFERROR(MODE(J13:P13),"OFF") -> 0.375 | Y13: 0.375
A14: =VLOOKUP(B14,Masterlist!B:E,2,) -> 245194 | B14: Rosally Maquirang Poblacion | C14: 0.375 | D14: 0.375 | E14: 0.375 | F14: OFF | G14: OFF | H14: 0.375 | I14: 0.375 | J14: OFF | K14: 0.375 | L14: 0.375 | M14: 0.375 | N14: 0.375 | O14: 0.375 | P14: OFF | Q14: OFF | R14: 0.375 | S14: 0.375 | T14: 0.375 | U14: 0.375 | V14: 0.375 | W14: OFF | X14: =IFERROR(MODE(J14:P14),"OFF") -> 0.375 | Y14: 0.375
A15: =VLOOKUP(B15,Masterlist!B:E,2,) -> 287483 | B15: Mary Jay Canag Cantomayor | C15: 0.375 | D15: 0.375 | E15: 0.375 | F15: OFF | G15: OFF | H15: 0.375 | I15: 0.375 | J15: OFF | K15: 0.375 | L15: 0.375 | M15: 0.375 | N15: 0.375 | O15: 0.375 | P15: OFF | Q15: OFF | R15: 0.375 | S15: 0.375 | T15: 0.375 | U15: 0.375 | V15: 0.375 | W15: OFF | X15: =IFERROR(MODE(J15:P15),"OFF") -> 0.375 | Y15: 0.375
A16: =VLOOKUP(B16,Masterlist!B:E,2,) -> 426497 | B16: Jackielyn,Cabanas,Faro | C16: 0.375 | D16: 0.375 | E16: 0.375 | F16: OFF | G16: OFF | H16: 0.375 | I16: 0.375 | J16: OFF | K16: 0.375 | L16: 0.375 | M16: 0.375 | N16: 0.375 | O16: 0.375 | P16: OFF | Q16: OFF | R16: 0.375 | S16: 0.375 | T16: 0.375 | U16: 0.375 | V16: 0.375 | W16: OFF | X16: =IFERROR(MODE(J16:P16),"OFF") -> 0.375 | Y16: 0.375
A17: =VLOOKUP(B17,Masterlist!B:E,2,) -> 482680 | B17: Perey Joy Torino | C17: 0.375 | D17: 0.375 | E17: 0.375 | F17: OFF | G17: OFF | H17: 0.375 | I17: 0.375 | J17: OFF | K17: 0.375 | L17: 0.375 | M17: 0.375 | N17: 0.375 | O17: 0.375 | P17: OFF | Q17: OFF | R17: 0.375 | S17: 0.375 | T17: 0.375 | U17: 0.375 | V17: 0.375 | W17: OFF | X17: =IFERROR(MODE(J17:P17),"OFF") -> 0.375 | Y17: 0.375
A18: =VLOOKUP(B18,Masterlist!B:E,2,) -> 420426 | B18: Ma. Lobell Trestiza | C18: 0.375 | D18: 0.375 | E18: 0.375 | F18: OFF | G18: OFF | H18: 0.375 | I18: 0.375 | J18: OFF | K18: 0.375 | L18: 0.375 | M18: 0.375 | N18: 0.375 | O18: 0.375 | P18: OFF | Q18: OFF | R18: 0.375 | S18: 0.375 | T18: 0.375 | U18: 0.375 | V18: 0.375 | W18: OFF | X18: =IFERROR(MODE(J18:P18),"OFF") -> 0.375 | Y18: 0.375
A19: =VLOOKUP(B19,Masterlist!B:E,2,) -> 486893 | B19: Rosevel Nagales | C19: 0.375 | D19: 0.375 | E19: 0.375 | F19: OFF | G19: OFF | H19: 0.375 | I19: 0.375 | J19: OFF | K19: 0.375 | L19: 0.375 | M19: 0.375 | N19: 0.375 | O19: 0.375 | P19: OFF | Q19: OFF | R19: 0.375 | S19: 0.375 | T19: 0.375 | U19: 0.375 | V19: 0.375 | W19: OFF | X19: =IFERROR(MODE(J19:P19),"OFF") -> 0.375 | Y19: 0.375
A20: =VLOOKUP(B20,Masterlist!B:E,2,) -> 501506 | B20: Johannah Salay | C20: 0.375 | D20: 0.375 | E20: 0.375 | F20: OFF | G20: OFF | H20: 0.375 | I20: 0.375 | J20: OFF | K20: 0.375 | L20: 0.375 | M20: 0.375 | N20: 0.375 | O20: 0.375 | P20: OFF | Q20: OFF | R20: 0.375 | S20: 0.375 | T20: 0.375 | U20: 0.375 | V20: 0.375 | W20: OFF | X20: =IFERROR(MODE(J20:P20),"OFF") -> 0.375 | Y20: 0.375
A21: =VLOOKUP(B21,Masterlist!B:E,2,) -> 305624 | B21: Emilie Cabaluna Gentroles | C21: 0.375 | D21: 0.375 | E21: 0.375 | F21: OFF | G21: OFF | H21: 0.375 | I21: 0.375 | J21: OFF | K21: 0.375 | L21: 0.375 | M21: 0.375 | N21: 0.375 | O21: 0.375 | P21: OFF | Q21: OFF | R21: 0.375 | S21: 0.375 | T21: 0.375 | U21: 0.375 | V21: 0.375 | W21: OFF | X21: =IFERROR(MODE(J21:P21),"OFF") -> 0.375 | Y21: 0.375
A22: =VLOOKUP(B22,Masterlist!B:E,2,) -> 380214 | B22: Romel,Concepcion,Resente | C22: 0.375 | D22: 0.375 | E22: 0.375 | F22: 0.375 | G22: 0.375 | H22: OFF | I22: OFF | J22: 0.375 | K22: 0.375 | L22: 0.375 | M22: 0.375 | N22: 0.375 | O22: OFF | P22: OFF | Q22: 0.375 | R22: 0.375 | S22: 0.375 | T22: 0.375 | U22: 0.375 | V22: OFF | W22: OFF | X22: =IFERROR(MODE(J22:P22),"OFF") -> 0.375 | Y22: OFF
A23: =VLOOKUP(B23,Masterlist!B:E,2,) -> 333358 | B23: Irene,Vasquez,Sarabia | C23: 0.375 | D23: 0.375 | E23: 0.375 | F23: 0.375 | G23: 0.375 | H23: OFF | I23: OFF | J23: 0.375 | K23: 0.375 | L23: 0.375 | M23: 0.375 | N23: 0.375 | O23: OFF | P23: OFF | Q23: 0.375 | R23: 0.375 | S23: 0.375 | T23: 0.375 | U23: 0.375 | V23: OFF | W23: OFF | X23: =IFERROR(MODE(J23:P23),"OFF") -> 0.375 | Y23: OFF
A24: =VLOOKUP(B24,Masterlist!B:E,2,) -> 380240 | B24: Mark Gil Apil Villagracia | C24: 0.375 | D24: 0.375 | E24: 0.375 | F24: 0.375 | G24: 0.375 | H24: OFF | I24: OFF | J24: 0.375 | K24: 0.375 | L24: 0.375 | M24: 0.375 | N24: 0.375 | O24: OFF | P24: OFF | Q24: 0.375 | R24: 0.375 | S24: 0.375 | T24: 0.375 | U24: 0.375 | V24: OFF | W24: OFF | X24: =IFERROR(MODE(J24:P24),"OFF") -> 0.375 | Y24: OFF
A25: =VLOOKUP(B25,Masterlist!B:E,2,) -> 339523 | B25: Ma Reslie,Estrellanes,Begaso | C25: 0.375 | D25: 0.375 | E25: 0.375 | F25: 0.375 | G25: 0.375 | H25: OFF | I25: OFF | J25: 0.375 | K25: 0.375 | L25: 0.375 | M25: 0.375 | N25: 0.375 | O25: OFF | P25: OFF | Q25: 0.375 | R25: 0.375 | S25: 0.375 | T25: 0.375 | U25: 0.375 | V25: OFF | W25: OFF | X25: =IFERROR(MODE(J25:P25),"OFF") -> 0.375 | Y25: OFF
A26: =VLOOKUP(B26,Masterlist!B:E,2,) -> 317122 | B26: Verlyn Rose,Aurora,Villaram | C26: 0.375 | D26: 0.375 | E26: 0.375 | F26: 0.375 | G26: 0.375 | H26: OFF | I26: OFF | J26: 0.375 | K26: 0.375 | L26: 0.375 | M26: 0.375 | N26: 0.375 | O26: OFF | P26: OFF | Q26: 0.375 | R26: 0.375 | S26: 0.375 | T26: 0.375 | U26: 0.375 | V26: OFF | W26: OFF | X26: =IFERROR(MODE(J26:P26),"OFF") -> 0.375 | Y26: OFF
A27: =VLOOKUP(B27,Masterlist!B:E,2,) -> 388996 | B27: Jelyn Zarate | C27: 0.375 | D27: 0.375 | E27: 0.375 | F27: 0.375 | G27: 0.375 | H27: OFF | I27: OFF | J27: 0.375 | K27: 0.375 | L27: 0.375 | M27: 0.375 | N27: 0.375 | O27: OFF | P27: OFF | Q27: 0.375 | R27: 0.375 | S27: 0.375 | T27: 0.375 | U27: 0.375 | V27: OFF | W27: OFF | X27: =IFERROR(MODE(J27:P27),"OFF") -> 0.375 | Y27: OFF
A28: =VLOOKUP(B28,Masterlist!B:E,2,) -> 456094 | B28: Gabriel Philip Delfin | C28: 0.375 | D28: 0.375 | E28: 0.375 | F28: 0.375 | G28: 0.375 | H28: OFF | I28: OFF | J28: 0.375 | K28: 0.375 | L28: 0.375 | M28: 0.375 | N28: 0.375 | O28: OFF | P28: OFF | Q28: 0.375 | R28: 0.375 | S28: 0.375 | T28: 0.375 | U28: 0.375 | V28: OFF | W28: OFF | X28: =IFERROR(MODE(J28:P28),"OFF") -> 0.375 | Y28: OFF
A29: =VLOOKUP(B29,Masterlist!B:E,2,) -> 260429 | B29: Charlotte,Selirio,Escalona | C29: 0.375 | D29: 0.375 | E29: 0.375 | F29: 0.375 | G29: 0.375 | H29: OFF | I29: OFF | J29: 0.375 | K29: 0.375 | L29: 0.375 | M29: 0.375 | N29: 0.375 | O29: OFF | P29: OFF | Q29: 0.375 | R29: 0.375 | S29: 0.375 | T29: 0.375 | U29: 0.375 | V29: OFF | W29: OFF | X29: =IFERROR(MODE(J29:P29),"OFF") -> 0.375 | Y29: OFF
A30: =VLOOKUP(B30,Masterlist!B:E,2,) -> 333053 | B30: Frank Lina,Sey,Ituriaga | C30: 0.375 | D30: 0.375 | E30: 0.375 | F30: 0.375 | G30: 0.375 | H30: OFF | I30: OFF | J30: 0.375 | K30: 0.375 | L30: 0.375 | M30: 0.375 | N30: 0.375 | O30: OFF | P30: OFF | Q30: 0.375 | R30: 0.375 | S30: 0.375 | T30: 0.375 | U30: 0.375 | V30: OFF | W30: OFF | X30: =IFERROR(MODE(J30:P30),"OFF") -> 0.375 | Y30: OFF
A31: =VLOOKUP(B31,Masterlist!B:E,2,) -> 487086 | B31: Ma. Eva Karina Remandaban | C31: 0.375 | D31: 0.375 | E31: 0.375 | F31: 0.375 | G31: 0.375 | H31: OFF | I31: OFF | J31: 0.375 | K31: 0.375 | L31: 0.375 | M31: 0.375 | N31: 0.375 | O31: OFF | P31: OFF | Q31: 0.375 | R31: 0.375 | S31: 0.375 | T31: 0.375 | U31: 0.375 | V31: OFF | W31: OFF | X31: =IFERROR(MODE(J31:P31),"OFF") -> 0.375 | Y31: OFF
A32: =VLOOKUP(B32,Masterlist!B:E,2,) -> 486898 | B32: Carmen Mae Huyong | C32: 0.375 | D32: 0.375 | E32: 0.375 | F32: 0.375 | G32: 0.375 | H32: OFF | I32: OFF | J32: 0.375 | K32: 0.375 | L32: 0.375 | M32: 0.375 | N32: 0.375 | O32: OFF | P32: OFF | Q32: 0.375 | R32: 0.375 | S32: 0.375 | T32: 0.375 | U32: 0.375 | V32: OFF | W32: OFF | X32: =IFERROR(MODE(J32:P32),"OFF") -> 0.375 | Y32: OFF
A33: =VLOOKUP(B33,Masterlist!B:E,2,) -> 487085 | B33: Ednel Alagon | C33: 0.375 | D33: 0.375 | E33: 0.375 | F33: 0.375 | G33: 0.375 | H33: OFF | I33: OFF | J33: 0.375 | K33: 0.375 | L33: 0.375 | M33: 0.375 | N33: 0.375 | O33: OFF | P33: OFF | Q33: 0.375 | R33: 0.375 | S33: 0.375 | T33: 0.375 | U33: 0.375 | V33: OFF | W33: OFF | X33: =IFERROR(MODE(J33:P33),"OFF") -> 0.375 | Y33: OFF
... A39: =VLOOKUP(B39,Masterlist!B:E,2,) -> 436396 | B39: Ma Joanne Girado Garcia | C39: 0.375 | D39: 0.375 | E39: 0.375 | F39: 0.375 | G39: 0.375 | H39: OFF | I39: OFF | J39: 0.375 | K39: 0.375 | L39: 0.375 | M39: 0.375 | N39: 0.375 | O39: OFF | P39: OFF | Q39: 0.375 | R39: 0.375 | S39: 0.375 | T39: 0.375 | U39: 0.375 | V39: OFF | W39: OFF | X39: =IFERROR(MODE(J39:P39),"OFF") -> 0.375 | Y39: OFF
A41: =VLOOKUP(B41,Masterlist!B:E,2,) -> 333148 | B41: Lemarie Garcia Aldaba | C41: 0.5 | D41: OFF | E41: 0.5 | F41: 0.5 | G41: OFF | H41: 0.5 | I41: 0.5 | J41: 0.5 | K41: 0.5 | L41: 0.5 | M41: OFF | N41: OFF | O41: 0.5 | P41: 0.5 | Q41: 0.5 | R41: 0.5 | S41: 0.5 | T41: OFF | U41: OFF | V41: 0.5 | W41: 0.5 | X41: =IFERROR(MODE(J41:P41),"OFF") -> 0.5 | Y41: 0.5
A42: =VLOOKUP(B42,Masterlist!B:E,2,) -> 509374 | B42: John Casper Villegas | C42: OFF | D42: OFF | E42: OFF | F42: OFF | G42: OFF | H42: OFF | I42: OFF | J42: OFF | K42: OFF | L42: OFF | M42: OFF | N42: OFF | O42: OFF | P42: OFF | Q42: OFF | R42: OFF | S42: OFF | T42: OFF | U42: OFF | V42: OFF | W42: OFF | X42: =IFERROR(MODE(J42:P42),"OFF") -> OFF | Y42: OFF
A43: =VLOOKUP(B43,Masterlist!B:E,2,) -> 509445 | B43: Kyla Tacuyan | C43: 0.5 | D43: OFF | E43: 0.5 | F43: 0.5 | G43: OFF | H43: 0.5 | I43: 0.5 | J43: 0.5 | K43: 0.5 | L43: 0.5 | M43: OFF | N43: OFF | O43: 0.5 | P43: 0.5 | Q43: 0.5 | R43: 0.5 | S43: 0.5 | T43: OFF | U43: OFF | V43: 0.5 | W43: 0.5 | X43: =IFERROR(MODE(J43:P43),"OFF") -> 0.5 | Y43: 0.5
A44: =VLOOKUP(B44,Masterlist!B:E,2,) -> 509526 | B44: Albert Cerdaña | C44: OFF | D44: OFF | E44: OFF | F44: OFF | G44: OFF | H44: OFF | I44: OFF | J44: OFF | K44: OFF | L44: OFF | M44: OFF | N44: OFF | O44: OFF | P44: OFF | Q44: OFF | R44: OFF | S44: OFF | T44: OFF | U44: OFF | V44: OFF | W44: OFF | X44: =IFERROR(MODE(J44:P44),"OFF") -> OFF | Y44: OFF
A45: =VLOOKUP(B45,Masterlist!B:E,2,) -> 509628 | B45: Cassey Mhae Aniversario | C45: 0.5 | D45: OFF | E45: 0.5 | F45: 0.5 | G45: OFF | H45: 0.5 | I45: 0.5 | J45: 0.5 | K45: 0.5 | L45: 0.5 | M45: OFF | N45: OFF | O45: 0.5 | P45: 0.5 | Q45: 0.5 | R45: 0.5 | S45: 0.5 | T45: OFF | U45: OFF | V45: 0.5 | W45: 0.5 | X45: =IFERROR(MODE(J45:P45),"OFF") -> 0.5 | Y45: 0.5
A46: =VLOOKUP(B46,Masterlist!B:E,2,) -> 511835 | B46: Ruby Ann Besin | C46: 0.5 | D46: OFF | E46: 0.5 | F46: 0.5 | G46: OFF | H46: 0.5 | I46: 0.5 | J46: 0.5 | K46: 0.5 | L46: 0.5 | M46: OFF | N46: OFF | O46: 0.5 | P46: 0.5 | Q46: 0.5 | R46: 0.5 | S46: 0.5 | T46: OFF | U46: OFF | V46: 0.5 | W46: 0.5 | X46: =IFERROR(MODE(J46:P46),"OFF") -> 0.5 | Y46: 0.5
...

Sheet Pavia
A1: Schedule (EST) | C1: ='Agent Sched'!C1:I1 -> WEEK BEGINNING 0427 | J1: ='Agent Sched'!J1:P1 -> WEEK BEGINNING 0504 | Q1: ='Agent Sched'!Q1:W1 -> WEEK BEGINNING 0511 | Y1: Prev Sun
A2: UID | B2: Agent Name | C2: Mon | D2: Tue | E2: Wed | F2: Thu | G2: Fri | H2: Sat | I2: Sun | J2: Mon | K2: Tue | L2: Wed | M2: Thu | N2: Fri | O2: Sat | P2: Sun | Q2: Mon | R2: Tue | S2: Wed | T2: Thu | U2: Fri | V2: Sat | W2: Sun | X2: Shift | Y2: Sun | AA2: Total
C3: ='Agent Sched'!C3 -> 46139 | D3: =C3+1 -> 46140 | E3: =D3+1 -> 46141 | F3: =E3+1 -> 46142 | G3: =F3+1 -> 46143 | H3: =G3+1 -> 46144 | I3: =H3+1 -> 46145 | J3: =I3+1 -> 46146 | K3: =J3+1 -> 46147 | ... W3: =V3+1 -> 46159 | Y3: =C3-1 -> 46138
A4: =VLOOKUP(B4,Masterlist!B:E,2,) -> 271192 | B4: Ann Dominique Ilustre Abada | C4: 0.375 | D4: OFF | E4: OFF | F4: 0.375 | G4: 0.375 | H4: 0.375 | I4: 0.375 | J4: 0.375 | K4: OFF | L4: OFF | M4: 0.375 | N4: 0.375 | O4: 0.375 | P4: 0.375 | Q4: 0.375 | R4: OFF | S4: OFF | T4: 0.375 | U4: 0.375 | V4: 0.375 | W4: 0.375 | X4: =IFERROR(MODE(J4:P4),"OFF") -> 0.375 | Y4: 0.375 | AA4: 0.375 | AB4: =COUNTIF(X:X,AA4) -> 22
A5: =VLOOKUP(B5,Masterlist!B:E,2,) -> 487057 | B5: Aya Banderado | C5: 0.375 | D5: OFF | E5: OFF | F5: 0.375 | G5: 0.375 | H5: 0.375 | I5: 0.375 | J5: 0.375 | K5: OFF | L5: OFF | M5: 0.375 | N5: 0.375 | O5: 0.375 | P5: 0.375 | Q5: 0.375 | R5: OFF | S5: OFF | T5: 0.375 | U5: 0.375 | V5: 0.375 | W5: 0.375 | X5: =IFERROR(MODE(J5:P5),"OFF") -> 0.375 | Y5: 0.375 | AA5: 0.625 | AB5: =COUNTIF(X:X,AA5) -> 0
A6: =VLOOKUP(B6,Masterlist!B:E,2,) -> 486751 | B6: Edrine Aaron Verdejo | C6: 0.375 | D6: OFF | E6: OFF | F6: 0.375 | G6: 0.375 | H6: 0.375 | I6: 0.375 | J6: 0.375 | K6: OFF | L6: OFF | M6: 0.375 | N6: 0.375 | O6: 0.375 | P6: 0.375 | Q6: 0.375 | R6: OFF | S6: OFF | T6: 0.375 | U6: 0.375 | V6: 0.375 | W6: 0.375 | X6: =IFERROR(MODE(J6:P6),"OFF") -> 0.375 | Y6: 0.375 | AA6: 0.66666667 | AB6: =COUNTIF(X:X,AA6) -> 10
A7: =VLOOKUP(B7,Masterlist!B:E,2,) -> 487312 | B7: Kent Gil | C7: 0.375 | D7: OFF | E7: OFF | F7: 0.375 | G7: 0.375 | H7: 0.375 | I7: 0.375 | J7: 0.375 | K7: OFF | L7: OFF | M7: 0.375 | N7: 0.375 | O7: 0.375 | P7: 0.375 | Q7: 0.375 | R7: OFF | S7: OFF | T7: 0.375 | U7: 0.375 | V7: 0.375 | W7: 0.375 | X7: =IFERROR(MODE(Q7:W7),"OFF") -> 0.375 | Y7: 0.375 | AA7: 0.5 | AB7: =COUNTIF(X:X,AA7) -> 4
A8: =VLOOKUP(B8,Masterlist!B:E,2,) -> 486784 | B8: Tim Justine Jover | C8: 0.375 | D8: OFF | E8: OFF | F8: 0.375 | G8: 0.375 | H8: 0.375 | I8: 0.375 | J8: 0.375 | K8: OFF | L8: OFF | M8: 0.375 | N8: 0.375 | O8: 0.375 | P8: 0.375 | Q8: 0.375 | R8: OFF | S8: OFF | T8: 0.375 | U8: 0.375 | V8: 0.375 | W8: 0.375 | X8: =IFERROR(MODE(Q8:W8),"OFF") -> 0.375 | Y8: 0.375 | AA8: 0.875 | AB8: =COUNTIF(X:X,AA8) -> 37
A9: =VLOOKUP(B9,Masterlist!B:E,2,) -> 486899 | B9: Allyzza Mae Ibañez | C9: 0.375 | D9: OFF | E9: OFF | F9: 0.375 | G9: 0.375 | H9: 0.375 | I9: 0.375 | J9: 0.375 | K9: OFF | L9: OFF | M9: 0.375 | N9: 0.375 | O9: 0.375 | P9: 0.375 | Q9: 0.375 | R9: OFF | S9: OFF | T9: 0.375 | U9: 0.375 | V9: 0.375 | W9: 0.375 | X9: =IFERROR(MODE(Q9:W9),"OFF") -> 0.375 | Y9: 0.375 | AB9: =SUM(AB4:AB8) -> 73
A10: =VLOOKUP(B10,Masterlist!B:E,2,) -> 487072 | B10: John Paul Rando | C10: 0.375 | D10: OFF | E10: OFF | F10: 0.375 | G10: 0.375 | H10: 0.375 | I10: 0.375 | J10: 0.375 | K10: OFF | L10: OFF | M10: 0.375 | N10: 0.375 | O10: 0.375 | P10: 0.375 | Q10: 0.375 | R10: OFF | S10: OFF | T10: 0.375 | U10: 0.375 | V10: 0.375 | W10: 0.375 | X10: =IFERROR(MODE(Q10:W10),"OFF") -> 0.375 | Y10: 0.375
A11: =VLOOKUP(B11,Masterlist!B:E,2,) -> 486891 | B11: Edamie Fajardo | C11: 0.375 | D11: OFF | E11: OFF | F11: 0.375 | G11: 0.375 | H11: 0.375 | I11: 0.375 | J11: 0.375 | K11: OFF | L11: OFF | M11: 0.375 | N11: 0.375 | O11: 0.375 | P11: 0.375 | Q11: 0.375 | R11: OFF | S11: OFF | T11: 0.375 | U11: 0.375 | V11: 0.375 | W11: 0.375 | X11: =IFERROR(MODE(Q11:W11),"OFF") -> 0.375 | Y11: 0.375
A12: =VLOOKUP(B12,Masterlist!B:E,2,) -> 486768 | B12: Francis Venise Armenton | C12: 0.375 | D12: OFF | E12: OFF | F12: 0.375 | G12: 0.375 | H12: 0.375 | I12: 0.375 | J12: 0.375 | K12: OFF | L12: OFF | M12: 0.375 | N12: 0.375 | O12: 0.375 | P12: 0.375 | Q12: 0.375 | R12: OFF | S12: OFF | T12: 0.375 | U12: 0.375 | V12: 0.375 | W12: 0.375 | X12: =IFERROR(MODE(Q12:W12),"OFF") -> 0.375 | Y12: 0.375
A13: =VLOOKUP(B13,Masterlist!B:E,2,) -> 501292 | B13: Mary Rose Alegre | C13: 0.375 | D13: OFF | E13: OFF | F13: 0.375 | G13: 0.375 | H13: 0.375 | I13: 0.375 | J13: 0.375 | K13: OFF | L13: OFF | M13: 0.375 | N13: 0.375 | O13: 0.375 | P13: 0.375 | Q13: 0.375 | R13: OFF | S13: OFF | T13: 0.375 | U13: 0.375 | V13: 0.375 | W13: 0.375 | X13: =IFERROR(MODE(Q13:W13),"OFF") -> 0.375 | Y13: 0.375
A14: =VLOOKUP(B14,Masterlist!B:E,2,) -> 501650 | B14: Regine Bajinting | C14: 0.375 | D14: OFF | E14: OFF | F14: 0.375 | G14: 0.375 | H14: 0.375 | I14: 0.375 | J14: 0.375 | K14: OFF | L14: OFF | M14: 0.375 | N14: 0.375 | O14: 0.375 | P14: 0.375 | Q14: 0.375 | R14: OFF | S14: OFF | T14: 0.375 | U14: 0.375 | V14: 0.375 | W14: 0.375 | X14: =IFERROR(MODE(Q14:W14),"OFF") -> 0.375 | Y14: 0.375
A15: =VLOOKUP(B15,Masterlist!B:E,2,) -> 264907 | B15: Lanie,Cabrera,Ramos | C15: 0.375 | D15: OFF | E15: OFF | F15: 0.375 | G15: 0.375 | H15: 0.375 | I15: 0.375 | J15: 0.375 | K15: OFF | L15: OFF | M15: 0.375 | N15: 0.375 | O15: 0.375 | P15: 0.375 | Q15: 0.375 | R15: OFF | S15: OFF | T15: 0.375 | U15: 0.375 | V15: 0.375 | W15: 0.375 | X15: =IFERROR(MODE(Q15:W15),"OFF") -> 0.375 | Y15: 0.375
A16: =VLOOKUP(B16,Masterlist!B:E,2,) -> 501297 | B16: Michael Jason Lencioco | C16: 0.375 | D16: OFF | E16: OFF | F16: 0.375 | G16: 0.375 | H16: 0.375 | I16: 0.375 | J16: 0.375 | K16: OFF | L16: OFF | M16: 0.375 | N16: 0.375 | O16: 0.375 | P16: 0.375 | Q16: 0.375 | R16: OFF | S16: OFF | T16: 0.375 | U16: 0.375 | V16: 0.375 | W16: 0.375 | X16: =IFERROR(MODE(Q16:W16),"OFF") -> 0.375 | Y16: 0.375
A17: =VLOOKUP(B17,Masterlist!B:E,2,) -> 501651 | B17: Leah May Baron | C17: 0.375 | D17: OFF | E17: OFF | F17: 0.375 | G17: 0.375 | H17: 0.375 | I17: 0.375 | J17: 0.375 | K17: OFF | L17: OFF | M17: 0.375 | N17: 0.375 | O17: 0.375 | P17: 0.375 | Q17: 0.375 | R17: OFF | S17: OFF | T17: 0.375 | U17: 0.375 | V17: 0.375 | W17: 0.375 | X17: =IFERROR(MODE(Q17:W17),"OFF") -> 0.375 | Y17: 0.375
A18: =VLOOKUP(B18,Masterlist!B:E,2,) -> 379708 | B18: Pressie Jean Costas | C18: 0.375 | D18: OFF | E18: OFF | F18: 0.375 | G18: 0.375 | H18: 0.375 | I18: 0.375 | J18: 0.375 | K18: OFF | L18: OFF | M18: 0.375 | N18: 0.375 | O18: 0.375 | P18: 0.375 | Q18: 0.375 | R18: OFF | S18: OFF | T18: 0.375 | U18: 0.375 | V18: 0.375 | W18: 0.375 | X18: =IFERROR(MODE(Q18:W18),"OFF") -> 0.375 | Y18: 0.375
A19: =VLOOKUP(B19,Masterlist!B:E,2,) -> 432336 | B19: Ladyvanessa Jalbuena | C19: 0.375 | D19: OFF | E19: OFF | F19: 0.375 | G19: 0.375 | H19: 0.375 | I19: 0.375 | J19: 0.375 | K19: OFF | L19: OFF | M19: 0.375 | N19: 0.375 | O19: 0.375 | P19: 0.375 | Q19: 0.375 | R19: OFF | S19: OFF | T19: 0.375 | U19: 0.375 | V19: 0.375 | W19: 0.375 | X19: =IFERROR(MODE(Q19:W19),"OFF") -> 0.375 | Y19: 0.375
A20: =VLOOKUP(B20,Masterlist!B:E,2,) -> 392978 | B20: Senemeah Pagsugiron | C20: 0.375 | D20: OFF | E20: OFF | F20: 0.375 | G20: 0.375 | H20: 0.375 | I20: 0.375 | J20: 0.375 | K20: OFF | L20: OFF | M20: 0.375 | N20: 0.375 | O20: 0.375 | P20: 0.375 | Q20: 0.375 | R20: OFF | S20: OFF | T20: 0.375 | U20: 0.375 | V20: 0.375 | W20: 0.375 | X20: =IFERROR(MODE(Q20:W20),"OFF") -> 0.375 | Y20: 0.375
A21: =VLOOKUP(B21,Masterlist!B:E,2,) -> 490833 | B21: Samfer Kim Ventura | C21: 0.375 | D21: OFF | E21: OFF | F21: 0.375 | G21: 0.375 | H21: 0.375 | I21: 0.375 | J21: 0.375 | K21: OFF | L21: OFF | M21: 0.375 | N21: 0.375 | O21: 0.375 | P21: 0.375 | Q21: 0.375 | R21: OFF | S21: OFF | T21: 0.375 | U21: 0.375 | V21: 0.375 | W21: 0.375 | X21: =IFERROR(MODE(Q21:W21),"OFF") -> 0.375 | Y21: 0.375
... A23: =VLOOKUP(B23,Masterlist!B:E,2,) -> 339582 | B23: Jason Jegonia | C23: 0.375 | D23: OFF | E23: OFF | F23: 0.375 | G23: 0.375 | H23: 0.375 | I23: 0.375 | J23: 0.375 | K23: OFF | L23: OFF | M23: 0.375 | N23: 0.375 | O23: 0.375 | P23: 0.375 | Q23: 0.375 | R23: OFF | S23: OFF | T23: 0.375 | U23: 0.375 | V23: 0.375 | W23: 0.375 | X23: =IFERROR(MODE(Q23:W23),"OFF") -> 0.375 | Y23: 0.375
A24: =VLOOKUP(B24,Masterlist!B:E,2,) -> 472371 | B24: Ariane Jane Mainar | C24: 0.375 | D24: 0.375 | E24: 0.375 | F24: 0.375 | G24: 0.375 | H24: OFF | I24: OFF | J24: 0.375 | K24: 0.375 | L24: 0.375 | M24: 0.375 | N24: 0.375 | O24: OFF | P24: OFF | Q24: 0.375 | R24: 0.375 | S24: 0.375 | T24: 0.375 | U24: 0.375 | V24: OFF | W24: OFF | X24: =IFERROR(MODE(J24:P24),"OFF") -> 0.375 | Y24: OFF
A25: =VLOOKUP(B25,Masterlist!B:E,2,) -> 487318 | B25: Shaun Mario Octaviano | C25: 0.375 | D25: 0.375 | E25: 0.375 | F25: 0.375 | G25: 0.375 | H25: OFF | I25: OFF | J25: 0.375 | K25: 0.375 | L25: 0.375 | M25: 0.375 | N25: 0.375 | O25: OFF | P25: OFF | Q25: 0.375 | R25: 0.375 | S25: 0.375 | T25: 0.375 | U25: 0.375 | V25: OFF | W25: OFF | X25: =IFERROR(MODE(J25:P25),"OFF") -> 0.375 | Y25: OFF
A26: =VLOOKUP(B26,Masterlist!B:E,2,) -> 509087 | B26: Clarisse Aujero | C26: 0.66666667 | D26: 0.66666667 | E26: OFF | F26: 0.66666667 | G26: 0.66666667 | H26: OFF | I26: 0.66666667 | J26: 0.66666667 | K26: 0.66666667 | L26: 0.66666667 | M26: 0.66666667 | N26: OFF | O26: OFF | P26: 0.66666667 | Q26: 0.66666667 | R26: 0.66666667 | S26: 0.66666667 | T26: 0.66666667 | U26: OFF | V26: OFF | W26: 0.66666667 | X26: =IFERROR(MODE(Q26:W26),"OFF") -> 0.66666667 | Y26: 0.58333333
A27: =VLOOKUP(B27,Masterlist!B:E,2,) -> 509096 | B27: Marck Lourence Racines | C27: 0.66666667 | D27: 0.66666667 | E27: OFF | F27: 0.66666667 | G27: 0.66666667 | H27: OFF | I27: 0.66666667 | J27: 0.66666667 | K27: 0.66666667 | L27: 0.66666667 | M27: 0.66666667 | N27: OFF | O27: OFF | P27: 0.66666667 | Q27: 0.66666667 | R27: 0.66666667 | S27: 0.66666667 | T27: 0.66666667 | U27: OFF | V27: OFF | W27: 0.66666667 | X27: =IFERROR(MODE(Q27:W27),"OFF") -> 0.66666667 | Y27: 0.58333333
A28: =VLOOKUP(B28,Masterlist!B:E,2,) -> 510345 | B28: Blossom Pearl Villorente | C28: 0.66666667 | D28: 0.66666667 | E28: 0.66666667 | F28: OFF | G28: OFF | H28: 0.66666667 | I28: 0.66666667 | J28: 0.66666667 | K28: 0.66666667 | L28: 0.66666667 | M28: OFF | N28: OFF | O28: 0.66666667 | P28: 0.66666667 | Q28: 0.66666667 | R28: 0.66666667 | S28: 0.66666667 | T28: OFF | U28: OFF | V28: 0.66666667 | W28: 0.66666667 | X28: =IFERROR(MODE(Q28:W28),"OFF") -> 0.66666667 | Y28: 0.58333333
A29: =VLOOKUP(B29,Masterlist!B:E,2,) -> 516493 | B29: Veneille Florence Siva | C29: 0.5 | D29: 0.5 | E29: OFF | F29: 0.5 | G29: 0.5 | H29: OFF | I29: 0.5 | J29: 0.5 | K29: 0.5 | L29: 0.5 | M29: 0.5 | N29: OFF | O29: OFF | P29: 0.5 | Q29: 0.5 | R29: 0.5 | S29: 0.5 | T29: 0.5 | U29: OFF | V29: OFF | W29: 0.5 | X29: =IFERROR(MODE(Q29:W29),"OFF") -> 0.5 | Y29: 0.5
A30: =VLOOKUP(B30,Masterlist!B:E,2,) -> 512673 | B30: Sheila Marie Casta | C30: 0.66666667 | D30: 0.66666667 | E30: OFF | F30: 0.66666667 | G30: 0.66666667 | H30: OFF | I30: 0.66666667 | J30: 0.66666667 | K30: 0.66666667 | L30: 0.66666667 | M30: 0.66666667 | N30: OFF | O30: OFF | P30: 0.66666667 | Q30: 0.66666667 | R30: 0.66666667 | S30: 0.66666667 | T30: 0.66666667 | U30: OFF | V30: OFF | W30: 0.66666667 | X30: =IFERROR(MODE(Q30:W30),"OFF") -> 0.66666667 | Y30: 0.58333333
A31: =VLOOKUP(B31,Masterlist!B:E,2,) -> 509708 | B31: Laurie Ann Billones | C31: 0.5 | D31: 0.5 | E31: OFF | F31: 0.5 | G31: 0.5 | H31: OFF | I31: 0.5 | J31: 0.5 | K31: 0.5 | L31: 0.5 | M31: 0.5 | N31: OFF | O31: OFF | P31: 0.5 | Q31: 0.5 | R31: 0.5 | S31: 0.5 | T31: 0.5 | U31: OFF | V31: OFF | W31: 0.5 | X31: =IFERROR(MODE(Q31:W31),"OFF") -> 0.5 | Y31: 0.5
A32: =VLOOKUP(B32,Masterlist!B:E,2,) -> 509378 | B32: Daisy Erlano | C32: 0.66666667 | D32: 0.66666667 | E32: OFF | F32: 0.66666667 | G32: 0.66666667 | H32: OFF | I32: 0.66666667 | J32: 0.66666667 | K32: 0.66666667 | L32: 0.66666667 | M32: 0.66666667 | N32: OFF | O32: OFF | P32: 0.66666667 | Q32: 0.66666667 | R32: 0.66666667 | S32: 0.66666667 | T32: 0.66666667 | U32: OFF | V32: OFF | W32: 0.66666667 | X32: =IFERROR(MODE(Q32:W32),"OFF") -> 0.66666667 | Y32: 0.58333333
A33: =VLOOKUP(B33,Masterlist!B:E,2,) -> 509525 | B33: Gicelle Dyan Carisma | C33: 0.66666667 | D33: 0.66666667 | E33: OFF | F33: 0.66666667 | G33: 0.66666667 | H33: OFF | I33: 0.66666667 | J33: 0.66666667 | K33: 0.66666667 | L33: 0.66666667 | M33: 0.66666667 | N33: OFF | O33: OFF | P33: 0.66666667 | Q33: 0.66666667 | R33: 0.66666667 | S33: 0.66666667 | T33: 0.66666667 | U33: OFF | V33: OFF | W33: 0.66666667 | X33: =IFERROR(MODE(Q33:W33),"OFF") -> 0.66666667 | Y33: 0.58333333
A34: =VLOOKUP(B34,Masterlist!B:E,2,) -> 512689 | B34: Floriden Aura Guino-o | C34: 0.5 | D34: 0.5 | E34: OFF | F34: 0.5 | G34: 0.5 | H34: OFF | I34: 0.5 | J34: 0.5 | K34: 0.5 | L34: 0.5 | M34: 0.5 | N34: OFF | O34: OFF | P34: 0.5 | Q34: 0.5 | R34: 0.5 | S34: 0.5 | T34: 0.5 | U34: OFF | V34: OFF | W34: 0.5 | X34: =IFERROR(MODE(Q34:W34),"OFF") -> 0.5 | Y34: 0.5
A35: =VLOOKUP(B35,Masterlist!B:E,2,) -> 512749 | B35: Medalyn Sealza | C35: 0.66666667 | D35: 0.66666667 | E35: OFF | F35: 0.66666667 | G35: 0.66666667 | H35: OFF | I35: 0.66666667 | J35: 0.66666667 | K35: 0.66666667 | L35: 0.66666667 | M35: 0.66666667 | N35: OFF | O35: OFF | P35: 0.66666667 | Q35: 0.66666667 | R35: 0.66666667 | S35: 0.66666667 | T35: 0.66666667 | U35: OFF | V35: OFF | W35: 0.66666667 | X35: =IFERROR(MODE(Q35:W35),"OFF") -> 0.66666667 | Y35: 0.58333333
A36: =VLOOKUP(B36,Masterlist!B:E,2,) -> 512732 | B36: April Grace Arrubio | C36: 0.66666667 | D36: 0.66666667 | E36: OFF | F36: 0.66666667 | G36: 0.66666667 | H36: OFF | I36: 0.66666667 | J36: 0.66666667 | K36: 0.66666667 | L36: 0.66666667 | M36: 0.66666667 | N36: OFF | O36: OFF | P36: 0.66666667 | Q36: 0.66666667 | R36: 0.66666667 | S36: 0.66666667 | T36: 0.66666667 | U36: OFF | V36: OFF | W36: 0.66666667 | X36: =IFERROR(MODE(Q36:W36),"OFF") -> 0.66666667 | Y36: 0.58333333
A37: =VLOOKUP(B37,Masterlist!B:E,2,) -> 516478 | B37: Amando Cadigal | C37: 0.5 | D37: 0.5 | E37: OFF | F37: 0.5 | G37: 0.5 | H37: OFF | I37: 0.5 | J37: 0.5 | K37: 0.5 | L37: 0.5 | M37: 0.5 | N37: OFF | O37: OFF | P37: 0.5 | Q37: 0.5 | R37: 0.5 | S37: 0.5 | T37: 0.5 | U37: OFF | V37: OFF | W37: 0.5 | X37: =IFERROR(MODE(Q37:W37),"OFF") -> 0.5 | Y37: 0.5
A38: =VLOOKUP(B38,Masterlist!B:E,2,) -> 516492 | B38: Winlord Christian Del Oeste | C38: 0.66666667 | D38: 0.66666667 | E38: OFF | F38: 0.66666667 | G38: 0.66666667 | H38: OFF | I38: 0.66666667 | J38: 0.66666667 | K38: 0.66666667 | L38: 0.66666667 | M38: 0.66666667 | N38: OFF | O38: OFF | P38: 0.66666667 | Q38: 0.66666667 | R38: 0.66666667 | S38: 0.66666667 | T38: 0.66666667 | U38: OFF | V38: OFF | W38: 0.66666667 | X38: =IFERROR(MODE(Q38:W38),"OFF") -> 0.66666667 | Y38: 0.58333333
A39: =VLOOKUP(B39,Masterlist!B:E,2,) -> 505816 | B39: Chzarl Mae Distajo | C39: 0.66666667 | D39: 0.66666667 | E39: OFF | F39: 0.66666667 | G39: 0.66666667 | H39: OFF | I39: 0.66666667 | J39: 0.66666667 | K39: 0.66666667 | L39: 0.66666667 | M39: 0.66666667 | N39: OFF | O39: OFF | P39: 0.66666667 | Q39: 0.66666667 | R39: 0.66666667 | S39: 0.66666667 | T39: 0.66666667 | U39: OFF | V39: OFF | W39: 0.66666667 | X39: =IFERROR(MODE(Q39:W39),"OFF") -> 0.66666667 | Y39: 0.58333333
A40: =VLOOKUP(B40,Masterlist!B:E,2,) -> 516334 | B40: Joanne Magampo | C40: 0.58333333 | D40: 0.58333333 | E40: 0.58333333 | F40: 0.58333333 | G40: 0.58333333 | H40: OFF | I40: OFF | J40: 0.58333333 | K40: 0.58333333 | L40: 0.58333333 | M40: 0.58333333 | N40: 0.58333333 | O40: OFF | P40: OFF | Q40: 0.58333333 | R40: 0.58333333 | S40: 0.58333333 | T40: 0.58333333 | U40: 0.58333333 | V40: OFF | W40: OFF | X40: =IFERROR(MODE(Q40:W40),"OFF") -> 0.58333333 | Y40: OFF
A41: =VLOOKUP(B41,Masterlist!B:E,2,) -> 516490 | B41: Shane Nicole Ladoing Provindido | C41: 0.58333333 | D41: 0.58333333 | E41: 0.58333333 | F41: 0.58333333 | G41: 0.58333333 | H41: OFF | I41: OFF | J41: 0.58333333 | K41: 0.58333333 | L41: 0.58333333 | M41: 0.58333333 | N41: 0.58333333 | O41: OFF | P41: OFF | Q41: 0.58333333 | R41: 0.58333333 | S41: 0.58333333 | T41: 0.58333333 | U41: 0.58333333 | V41: OFF | W41: OFF | X41: =IFERROR(MODE(Q41:W41),"OFF") -> 0.58333333 | Y41: OFF
...

Sheet Nesting Sched
A1: Schedule (EST) | C1: ='Agent Sched'!C1:I1 -> WEEK BEGINNING 0427 | J1: ='Agent Sched'!J1:P1 -> WEEK BEGINNING 0504 | Q1: ='Agent Sched'!Q1:W1 -> WEEK BEGINNING 0511 | Y1: Prev Sun
A2: Agent Lookup | B2: Agent Name | C2: Mon | D2: Tue | E2: Wed | F2: Thu | G2: Fri | H2: Sat | I2: Sun | J2: Mon | K2: Tue | L2: Wed | M2: Thu | N2: Fri | O2: Sat | P2: Sun | Q2: Mon | R2: Tue | S2: Wed | T2: Thu | U2: Fri | V2: Sat | W2: Sun | X2: Shift | Y2: Sun
C3: ='Agent Sched'!C3 -> 46139 | D3: =C3+1 -> 46140 | E3: =D3+1 -> 46141 | F3: =E3+1 -> 46142 | G3: =F3+1 -> 46143 | H3: =G3+1 -> 46144 | I3: =H3+1 -> 46145 | J3: =I3+1 -> 46146 | K3: =J3+1 -> 46147 | ... W3: =V3+1 -> 46159 | Y3: =C3-1 -> 46138 | AB3: 0.625 | AC3: =COUNTIF(X:X,AB3) -> 0
A4: =VLOOKUP(B4,Masterlist!B:D,2,) -> 524596 | B4: Jave Lowelle Valiente Gayangos | C4: 0.58333333 | D4: OFF | E4: 0.58333333 | F4: 0.58333333 | G4: 0.58333333 | H4: OFF | I4: 0.58333333 | J4: 0.58333333 | K4: 0.58333333 | L4: 0.58333333 | M4: 0.58333333 | N4: OFF | O4: OFF | P4: 0.58333333 | Q4: 0.58333333 | R4: 0.58333333 | S4: 0.58333333 | T4: 0.58333333 | U4: OFF | V4: OFF | W4: 0.58333333 | X4: =MODE(Q4:W4) -> 0.58333333 | Y4: 0.58333333
A5: =VLOOKUP(B5,Masterlist!B:D,2,) -> 524598 | B5: Nicka Mae De Los Reyes Porras | C5: 0.58333333 | D5: OFF | E5: 0.58333333 | F5: 0.58333333 | G5: 0.58333333 | H5: OFF | I5: 0.58333333 | J5: 0.58333333 | K5: 0.58333333 | L5: 0.58333333 | M5: 0.58333333 | N5: OFF | O5: OFF | P5: 0.58333333 | Q5: 0.58333333 | R5: 0.58333333 | S5: 0.58333333 | T5: 0.58333333 | U5: OFF | V5: OFF | W5: 0.58333333 | X5: =MODE(Q5:W5) -> 0.58333333 | Y5: 0.58333333
A6: =VLOOKUP(B6,Masterlist!B:D,2,) -> 524599 | B6: Roxan Sabido Sacay | C6: OFF | D6: OFF | E6: OFF | F6: OFF | G6: OFF | H6: OFF | I6: OFF | J6: OFF | K6: OFF | L6: OFF | M6: OFF | N6: OFF | O6: OFF | P6: OFF | Q6: OFF | R6: OFF | S6: OFF | T6: OFF | U6: OFF | V6: OFF | W6: OFF | X6: =MODE(Q6:W6) -> #N/A | Y6: OFF
A7: =VLOOKUP(B7,Masterlist!B:D,2,) -> 524593 | B7: Mikhaela Palma Detera | C7: 0.58333333 | D7: OFF | E7: 0.58333333 | F7: 0.58333333 | G7: 0.58333333 | H7: OFF | I7: 0.58333333 | J7: 0.58333333 | K7: 0.58333333 | L7: 0.58333333 | M7: 0.58333333 | N7: OFF | O7: OFF | P7: 0.58333333 | Q7: 0.58333333 | R7: 0.58333333 | S7: 0.58333333 | T7: 0.58333333 | U7: OFF | V7: OFF | W7: 0.58333333 | X7: =MODE(Q7:W7) -> 0.58333333 | Y7: 0.58333333
A8: =VLOOKUP(B8,Masterlist!B:D,2,) -> 524591 | B8: Jenel Prieto Advincula | C8: 0.58333333 | D8: OFF | E8: 0.58333333 | F8: 0.58333333 | G8: 0.58333333 | H8: OFF | I8: 0.58333333 | J8: 0.58333333 | K8: 0.58333333 | L8: 0.58333333 | M8: 0.58333333 | N8: OFF | O8: OFF | P8: 0.58333333 | Q8: 0.58333333 | R8: 0.58333333 | S8: 0.58333333 | T8: 0.58333333 | U8: OFF | V8: OFF | W8: 0.58333333 | X8: =MODE(Q8:W8) -> 0.58333333 | Y8: 0.58333333
A9: =VLOOKUP(B9,Masterlist!B:D,2,) -> 524600 | B9: John Federico Alfonso Tribunal Teruel | C9: 0.58333333 | D9: OFF | E9: 0.58333333 | F9: 0.58333333 | G9: 0.58333333 | H9: OFF | I9: 0.58333333 | J9: 0.58333333 | K9: 0.58333333 | L9: 0.58333333 | M9: 0.58333333 | N9: OFF | O9: OFF | P9: 0.58333333 | Q9: 0.58333333 | R9: 0.58333333 | S9: 0.58333333 | T9: 0.58333333 | U9: OFF | V9: OFF | W9: 0.58333333 | X9: =MODE(Q9:W9) -> 0.58333333 | Y9: 0.58333333
A10: =VLOOKUP(B10,Masterlist!B:D,2,) -> 524597 | B10: Jevel Von Bance Grate | C10: 0.58333333 | D10: OFF | E10: 0.58333333 | F10: 0.58333333 | G10: 0.58333333 | H10: OFF | I10: 0.58333333 | J10: 0.58333333 | K10: 0.58333333 | L10: 0.58333333 | M10: 0.58333333 | N10: OFF | O10: OFF | P10: 0.58333333 | Q10: 0.58333333 | R10: 0.58333333 | S10: 0.58333333 | T10: 0.58333333 | U10: OFF | V10: OFF | W10: 0.58333333 | X10: =MODE(Q10:W10) -> 0.58333333 | Y10: 0.58333333
A11: =VLOOKUP(B11,Masterlist!B:D,2,) -> 524595 | B11: Maxine Pabillo Duenas | C11: 0.58333333 | D11: OFF | E11: 0.58333333 | F11: 0.58333333 | G11: 0.58333333 | H11: OFF | I11: 0.58333333 | J11: 0.58333333 | K11: 0.58333333 | L11: 0.58333333 | M11: 0.58333333 | N11: OFF | O11: OFF | P11: 0.58333333 | Q11: 0.58333333 | R11: 0.58333333 | S11: 0.58333333 | T11: 0.58333333 | U11: OFF | V11: OFF | W11: 0.58333333 | X11: =MODE(Q11:W11) -> 0.58333333 | Y11: 0.58333333
A12: =VLOOKUP(B12,Masterlist!B:D,2,) -> 524594 | B12: Sittie Sufiyah Macaumbang Dimaampao | C12: 0.58333333 | D12: OFF | E12: 0.58333333 | F12: 0.58333333 | G12: 0.58333333 | H12: OFF | I12: 0.58333333 | J12: 0.58333333 | K12: 0.58333333 | L12: 0.58333333 | M12: 0.58333333 | N12: OFF | O12: OFF | P12: 0.58333333 | Q12: 0.58333333 | R12: 0.58333333 | S12: 0.58333333 | T12: 0.58333333 | U12: OFF | V12: OFF | W12: 0.58333333 | X12: =MODE(Q12:W12) -> 0.58333333 | Y12: 0.58333333
A13: =VLOOKUP(B13,Masterlist!B:D,2,) -> 524592 | B13: Ana Marie Albao | C13: 0.58333333 | D13: OFF | E13: 0.58333333 | F13: 0.58333333 | G13: 0.58333333 | H13: OFF | I13: 0.58333333 | J13: 0.58333333 | K13: 0.58333333 | L13: 0.58333333 | M13: 0.58333333 | N13: OFF | O13: OFF | P13: 0.58333333 | Q13: 0.58333333 | R13: 0.58333333 | S13: 0.58333333 | T13: 0.58333333 | U13: OFF | V13: OFF | W13: 0.58333333 | X13: =MODE(Q13:W13) -> 0.58333333 | Y13: 0.58333333
A62: Agents on RD | C62: =COUNTIF(C4:C54,"OFF") -> 1 | D62: =COUNTIF(D4:D54,"OFF") -> 10 | E62: =COUNTIF(E4:E54,"OFF") -> 1 | F62: =COUNTIF(F4:F54,"OFF") -> 1 | G62: =COUNTIF(G4:G54,"OFF") -> 1 | H62: =COUNTIF(H4:H54,"OFF") -> 10 | I62: =COUNTIF(I4:I54,"OFF") -> 1 | J62: =COUNTIF(J4:J54,"OFF") -> 1 | ... W62: =COUNTIF(W4:W54,"OFF") -> 1
A63: Agents on PTO | C63: =COUNTIF(C4:C61,"PTO") -> 0 | D63: =COUNTIF(D4:D61,"PTO") -> 0 | E63: =COUNTIF(E4:E61,"PTO") -> 0 | F63: =COUNTIF(F4:F61,"PTO") -> 0 | G63: =COUNTIF(G4:G61,"PTO") -> 0 | H63: =COUNTIF(H4:H61,"PTO") -> 0 | I63: =COUNTIF(I4:I61,"PTO") -> 0 | J63: =COUNTIF(J4:J61,"PTO") -> 0 | ... W63: =COUNTIF(W4:W61,"PTO") -> 0
A64: Agents on LOA | C64: =COUNTIF(C4:C61,"LOA") -> 0 | D64: =COUNTIF(D4:D61,"LOA") -> 0 | E64: =COUNTIF(E4:E61,"LOA") -> 0 | F64: =COUNTIF(F4:F61,"LOA") -> 0 | G64: =COUNTIF(G4:G61,"LOA") -> 0 | H64: =COUNTIF(H4:H61,"LOA") -> 0 | I64: =COUNTIF(I4:I61,"LOA") -> 0 | J64: =COUNTIF(J4:J61,"LOA") -> 0 | ... W64: =COUNTIF(W4:W61,"LOA") -> 0
A65: Agents Absent | C65: =COUNTIF(C4:C61,"A") -> 0 | D65: =COUNTIF(D4:D61,"A") -> 0 | E65: =COUNTIF(E4:E61,"A") -> 0 | F65: =COUNTIF(F4:F61,"A") -> 0 | G65: =COUNTIF(G4:G61,"A") -> 0 | H65: =COUNTIF(H4:H61,"A") -> 0 | I65: =COUNTIF(I4:I61,"A") -> 0 | J65: =COUNTIF(J4:J61,"A") -> 0 | ... W65: =COUNTIF(W4:W61,"A") -> 0
A66: Agents Scheduled | C66: =30-C62-C63-C64-C65 -> 29 | D66: =30-D62-D63-D64-D65 -> 20 | E66: =30-E62-E63-E64-E65 -> 29 | F66: =30-F62-F63-F64-F65 -> 29 | G66: =30-G62-G63-G64-G65 -> 29 | H66: =30-H62-H63-H64-H65 -> 20 | I66: =30-I62-I63-I64-I65 -> 29 | J66: =30-J62-J63-J64-J65 -> 29 | ... W66: =30-W62-W63-W64-W65 -> 29
A67: Total FTE/Headcount | C67: =SUM(C62:C66) -> 30 | D67: =SUM(D62:D66) -> 30 | E67: =SUM(E62:E66) -> 30 | F67: =SUM(F62:F66) -> 30 | G67: =SUM(G62:G66) -> 30 | H67: =SUM(H62:H66) -> 30 | I67: =SUM(I62:I66) -> 30 | J67: =SUM(J62:J66) -> 30 | ... W67: =SUM(W62:W66) -> 30
A68: OT NEEDED | C68: =COUNTIF(C4:C23,"OT")*7.5 -> 0 | D68: =COUNTIF(D4:D23,"OT")*7.5 -> 0 | E68: =COUNTIF(E4:E23,"OT")*7.5 -> 0 | F68: =COUNTIF(F4:F23,"OT")*7.5 -> 0 | G68: =COUNTIF(G4:G23,"OT")*7.5 -> 0 | H68: =COUNTIF(H4:H23,"OT")*7.5 -> 0 | I68: =COUNTIF(I4:I23,"OT")*7.5 -> 0 | J68: =COUNTIF(J4:J23,"OT")*7.5 -> 0 | ... W68: =COUNTIF(W4:W23,"OT")*7.5 -> 0
A71: Schedule (MNL) | C71: =C1 -> WEEK BEGINNING 0427 | J71: =J1 -> WEEK BEGINNING 0504 | Q71: =Q1 -> WEEK BEGINNING 0511
C72: Mon | D72: Tue | E72: Wed | F72: Thu | G72: Fri | H72: Sat | I72: Sun | J72: Mon | K72: Tue | L72: Wed | M72: Thu | N72: Fri | O72: Sat | P72: Sun | Q72: Mon | R72: Tue | S72: Wed | T72: Thu | U72: Fri | V72: Sat | W72: Sun
A73: Agent Lookup | B73: Agent Name | C73: =C3 -> 46139 | D73: =C73+1 -> 46140 | E73: =D73+1 -> 46141 | F73: =E73+1 -> 46142 | G73: =F73+1 -> 46143 | H73: =G73+1 -> 46144 | I73: =H73+1 -> 46145 | J73: =I73+1 -> 46146 | K73: =J73+1 -> 46147 | ... W73: =V73+1 -> 46159
A74: =B4 -> Jave Lowelle Valiente Gayangos | B74: =VLOOKUP(A74,Masterlist!B:D,3,) -> Jane Sairah Arac | C74: =IFERROR(IF(Y4= "PTO", "PTO",Y4+"12:00"),"OFF") -> 1.0833333 | D74: =IFERROR(IF(C4= "PTO", "PTO",C4+"12:00"),"OFF") -> 1.0833333 | E74: =IFERROR(IF(D4= "PTO", "PTO",D4+"12:00"),"OFF") -> OFF | F74: =IFERROR(IF(E4= "PTO", "PTO",E4+"12:00"),"OFF") -> 1.0833333 | G74: =IFERROR(IF(F4= "PTO", "PTO",F4+"12:00"),"OFF") -> 1.0833333 | H74: =IFERROR(IF(G4= "PTO", "PTO",G4+"12:00"),"OFF") -> 1.0833333 | I74: =IFERROR(IF(H4= "PTO", "PTO",H4+"12:00"),"OFF") -> OFF | J74: =IFERROR(IF(I4= "PTO", "PTO",I4+"12:00"),"OFF") -> 1.0833333 | K74: =IFERROR(IF(J4= "PTO", "PTO",J4+"12:00"),"OFF") -> 1.0833333 | ... W74: =IFERROR(IF(V4= "PTO", "PTO",V4+"12:00"),"OFF") -> OFF
A75: =B5 -> Nicka Mae De Los Reyes Porras | B75: =VLOOKUP(A75,Masterlist!B:D,3,) -> - | C75: =IFERROR(IF(Y5= "PTO", "PTO",Y5+"12:00"),"OFF") -> 1.0833333 | D75: =IFERROR(IF(C5= "PTO", "PTO",C5+"12:00"),"OFF") -> 1.0833333 | E75: =IFERROR(IF(D5= "PTO", "PTO",D5+"12:00"),"OFF") -> OFF | F75: =IFERROR(IF(E5= "PTO", "PTO",E5+"12:00"),"OFF") -> 1.0833333 | G75: =IFERROR(IF(F5= "PTO", "PTO",F5+"12:00"),"OFF") -> 1.0833333 | H75: =IFERROR(IF(G5= "PTO", "PTO",G5+"12:00"),"OFF") -> 1.0833333 | I75: =IFERROR(IF(H5= "PTO", "PTO",H5+"12:00"),"OFF") -> OFF | J75: =IFERROR(IF(I5= "PTO", "PTO",I5+"12:00"),"OFF") -> 1.0833333 | K75: =IFERROR(IF(J5= "PTO", "PTO",J5+"12:00"),"OFF") -> 1.0833333 | ... W75: =IFERROR(IF(V5= "PTO", "PTO",V5+"12:00"),"OFF") -> OFF
A76: =B6 -> Roxan Sabido Sacay | B76: =VLOOKUP(A76,Masterlist!B:D,3,) -> Jane Sairah Arac | C76: =IFERROR(IF(Y6= "PTO", "PTO",Y6+"12:00"),"OFF") -> OFF | D76: =IFERROR(IF(C6= "PTO", "PTO",C6+"12:00"),"OFF") -> OFF | E76: =IFERROR(IF(D6= "PTO", "PTO",D6+"12:00"),"OFF") -> OFF | F76: =IFERROR(IF(E6= "PTO", "PTO",E6+"12:00"),"OFF") -> OFF | G76: =IFERROR(IF(F6= "PTO", "PTO",F6+"12:00"),"OFF") -> OFF | H76: =IFERROR(IF(G6= "PTO", "PTO",G6+"12:00"),"OFF") -> OFF | I76: =IFERROR(IF(H6= "PTO", "PTO",H6+"12:00"),"OFF") -> OFF | J76: =IFERROR(IF(I6= "PTO", "PTO",I6+"12:00"),"OFF") -> OFF | K76: =IFERROR(IF(J6= "PTO", "PTO",J6+"12:00"),"OFF") -> OFF | ... W76: =IFERROR(IF(V6= "PTO", "PTO",V6+"12:00"),"OFF") -> OFF
A77: =B7 -> Mikhaela Palma Detera | B77: =VLOOKUP(A77,Masterlist!B:D,3,) -> Jane Sairah Arac | C77: =IFERROR(IF(Y7= "PTO", "PTO",Y7+"12:00"),"OFF") -> 1.0833333 | D77: =IFERROR(IF(C7= "PTO", "PTO",C7+"12:00"),"OFF") -> 1.0833333 | E77: =IFERROR(IF(D7= "PTO", "PTO",D7+"12:00"),"OFF") -> OFF | F77: =IFERROR(IF(E7= "PTO", "PTO",E7+"12:00"),"OFF") -> 1.0833333 | G77: =IFERROR(IF(F7= "PTO", "PTO",F7+"12:00"),"OFF") -> 1.0833333 | H77: =IFERROR(IF(G7= "PTO", "PTO",G7+"12:00"),"OFF") -> 1.0833333 | I77: =IFERROR(IF(H7= "PTO", "PTO",H7+"12:00"),"OFF") -> OFF | J77: =IFERROR(IF(I7= "PTO", "PTO",I7+"12:00"),"OFF") -> 1.0833333 | K77: =IFERROR(IF(J7= "PTO", "PTO",J7+"12:00"),"OFF") -> 1.0833333 | ... W77: =IFERROR(IF(V7= "PTO", "PTO",V7+"12:00"),"OFF") -> OFF
A78: =B8 -> Jenel Prieto Advincula | B78: =VLOOKUP(A78,Masterlist!B:D,3,) -> Jane Sairah Arac | C78: =IFERROR(IF(Y8= "PTO", "PTO",Y8+"12:00"),"OFF") -> 1.0833333 | D78: =IFERROR(IF(C8= "PTO", "PTO",C8+"12:00"),"OFF") -> 1.0833333 | E78: =IFERROR(IF(D8= "PTO", "PTO",D8+"12:00"),"OFF") -> OFF | F78: =IFERROR(IF(E8= "PTO", "PTO",E8+"12:00"),"OFF") -> 1.0833333 | G78: =IFERROR(IF(F8= "PTO", "PTO",F8+"12:00"),"OFF") -> 1.0833333 | H78: =IFERROR(IF(G8= "PTO", "PTO",G8+"12:00"),"OFF") -> 1.0833333 | I78: =IFERROR(IF(H8= "PTO", "PTO",H8+"12:00"),"OFF") -> OFF | J78: =IFERROR(IF(I8= "PTO", "PTO",I8+"12:00"),"OFF") -> 1.0833333 | K78: =IFERROR(IF(J8= "PTO", "PTO",J8+"12:00"),"OFF") -> 1.0833333 | ... W78: =IFERROR(IF(V8= "PTO", "PTO",V8+"12:00"),"OFF") -> OFF
A79: =B9 -> John Federico Alfonso Tribunal Teruel | B79: =VLOOKUP(A79,Masterlist!B:D,3,) -> Jane Sairah Arac | C79: =IFERROR(IF(Y9= "PTO", "PTO",Y9+"12:00"),"OFF") -> 1.0833333 | D79: =IFERROR(IF(C9= "PTO", "PTO",C9+"12:00"),"OFF") -> 1.0833333 | E79: =IFERROR(IF(D9= "PTO", "PTO",D9+"12:00"),"OFF") -> OFF | F79: =IFERROR(IF(E9= "PTO", "PTO",E9+"12:00"),"OFF") -> 1.0833333 | G79: =IFERROR(IF(F9= "PTO", "PTO",F9+"12:00"),"OFF") -> 1.0833333 | H79: =IFERROR(IF(G9= "PTO", "PTO",G9+"12:00"),"OFF") -> 1.0833333 | I79: =IFERROR(IF(H9= "PTO", "PTO",H9+"12:00"),"OFF") -> OFF | J79: =IFERROR(IF(I9= "PTO", "PTO",I9+"12:00"),"OFF") -> 1.0833333 | K79: =IFERROR(IF(J9= "PTO", "PTO",J9+"12:00"),"OFF") -> 1.0833333 | ... W79: =IFERROR(IF(V9= "PTO", "PTO",V9+"12:00"),"OFF") -> OFF
A80: =B10 -> Jevel Von Bance Grate | B80: =VLOOKUP(A80,Masterlist!B:D,3,) -> Jane Sairah Arac | C80: =IFERROR(IF(Y10= "PTO", "PTO",Y10+"12:00"),"OFF") -> 1.0833333 | D80: =IFERROR(IF(C10= "PTO", "PTO",C10+"12:00"),"OFF") -> 1.0833333 | E80: =IFERROR(IF(D10= "PTO", "PTO",D10+"12:00"),"OFF") -> OFF | F80: =IFERROR(IF(E10= "PTO", "PTO",E10+"12:00"),"OFF") -> 1.0833333 | G80: =IFERROR(IF(F10= "PTO", "PTO",F10+"12:00"),"OFF") -> 1.0833333 | H80: =IFERROR(IF(G10= "PTO", "PTO",G10+"12:00"),"OFF") -> 1.0833333 | I80: =IFERROR(IF(H10= "PTO", "PTO",H10+"12:00"),"OFF") -> OFF | J80: =IFERROR(IF(I10= "PTO", "PTO",I10+"12:00"),"OFF") -> 1.0833333 | K80: =IFERROR(IF(J10= "PTO", "PTO",J10+"12:00"),"OFF") -> 1.0833333 | ... W80: =IFERROR(IF(V10= "PTO", "PTO",V10+"12:00"),"OFF") -> OFF
A81: =B11 -> Maxine Pabillo Duenas | B81: =VLOOKUP(A81,Masterlist!B:D,3,) -> Jane Sairah Arac | C81: =IFERROR(IF(Y11= "PTO", "PTO",Y11+"12:00"),"OFF") -> 1.0833333 | D81: =IFERROR(IF(C11= "PTO", "PTO",C11+"12:00"),"OFF") -> 1.0833333 | E81: =IFERROR(IF(D11= "PTO", "PTO",D11+"12:00"),"OFF") -> OFF | F81: =IFERROR(IF(E11= "PTO", "PTO",E11+"12:00"),"OFF") -> 1.0833333 | G81: =IFERROR(IF(F11= "PTO", "PTO",F11+"12:00"),"OFF") -> 1.0833333 | H81: =IFERROR(IF(G11= "PTO", "PTO",G11+"12:00"),"OFF") -> 1.0833333 | I81: =IFERROR(IF(H11= "PTO", "PTO",H11+"12:00"),"OFF") -> OFF | J81: =IFERROR(IF(I11= "PTO", "PTO",I11+"12:00"),"OFF") -> 1.0833333 | K81: =IFERROR(IF(J11= "PTO", "PTO",J11+"12:00"),"OFF") -> 1.0833333 | ... W81: =IFERROR(IF(V11= "PTO", "PTO",V11+"12:00"),"OFF") -> OFF
A82: =B12 -> Sittie Sufiyah Macaumbang Dimaampao | B82: =VLOOKUP(A82,Masterlist!B:D,3,) -> Jane Sairah Arac | C82: =IFERROR(IF(Y12= "PTO", "PTO",Y12+"12:00"),"OFF") -> 1.0833333 | D82: =IFERROR(IF(C12= "PTO", "PTO",C12+"12:00"),"OFF") -> 1.0833333 | E82: =IFERROR(IF(D12= "PTO", "PTO",D12+"12:00"),"OFF") -> OFF | F82: =IFERROR(IF(E12= "PTO", "PTO",E12+"12:00"),"OFF") -> 1.0833333 | G82: =IFERROR(IF(F12= "PTO", "PTO",F12+"12:00"),"OFF") -> 1.0833333 | H82: =IFERROR(IF(G12= "PTO", "PTO",G12+"12:00"),"OFF") -> 1.0833333 | I82: =IFERROR(IF(H12= "PTO", "PTO",H12+"12:00"),"OFF") -> OFF | J82: =IFERROR(IF(I12= "PTO", "PTO",I12+"12:00"),"OFF") -> 1.0833333 | K82: =IFERROR(IF(J12= "PTO", "PTO",J12+"12:00"),"OFF") -> 1.0833333 | ... W82: =IFERROR(IF(V12= "PTO", "PTO",V12+"12:00"),"OFF") -> OFF
A83: =B13 -> Ana Marie Albao | B83: =VLOOKUP(A83,Masterlist!B:D,3,) -> - | C83: =IFERROR(IF(Y13= "PTO", "PTO",Y13+"12:00"),"OFF") -> 1.0833333 | D83: =IFERROR(IF(C13= "PTO", "PTO",C13+"12:00"),"OFF") -> 1.0833333 | E83: =IFERROR(IF(D13= "PTO", "PTO",D13+"12:00"),"OFF") -> OFF | F83: =IFERROR(IF(E13= "PTO", "PTO",E13+"12:00"),"OFF") -> 1.0833333 | G83: =IFERROR(IF(F13= "PTO", "PTO",F13+"12:00"),"OFF") -> 1.0833333 | H83: =IFERROR(IF(G13= "PTO", "PTO",G13+"12:00"),"OFF") -> 1.0833333 | I83: =IFERROR(IF(H13= "PTO", "PTO",H13+"12:00"),"OFF") -> OFF | J83: =IFERROR(IF(I13= "PTO", "PTO",I13+"12:00"),"OFF") -> 1.0833333 | K83: =IFERROR(IF(J13= "PTO", "PTO",J13+"12:00"),"OFF") -> 1.0833333 | ... W83: =IFERROR(IF(V13= "PTO", "PTO",V13+"12:00"),"OFF") -> OFF

Sheet Nesting Staffing
B1: WEEK 1 | T1: WEEK 2 | AI1: WEEK 3 | AX1: WNS Core Hours | BG1: WEEK 1 | BH1: WNS Additional Support | BU1: WEEK 1 | CB1: WEEK 2 | CI1: WEEK 3 | CS1: 6
A2: Agent Name | B2: Mon | C2: Mon | D2: Tue | E2: Tue | F2: Wed | G2: Wed | H2: Thur | I2: Thur | J2: Fri | K2: Fri | L2: Sat | M2: Sat | N2: Sun | O2: Sun | Q2: Prev Sun | R2: Prev Sun | T2: Mon | U2: Mon | V2: Tue | W2: Tue | X2: Wed | Y2: Wed | Z2: Thur | AA2: Thur | AB2: Fri | AC2: Fri | AD2: Sat | AE2: Sat | AF2: Sun | AG2: Sun | AI2: Mon | AJ2: Mon | AK2: Tue | AL2: Tue | AM2: Wed | AN2: Wed | AO2: Thur | AP2: Thur | AQ2: Fri | AR2: Fri | AS2: Sat | AT2: Sat | AU2: Sun | AV2: Sun | AX2: Interval | AY2: NEXT DAY | AZ2: Mon | BA2: Tue | BB2: Wed | BC2: Thu | BD2: Fri | BE2: Sat | BF2: Sun | BH2: Interval | BI2: NEXT DAY | BJ2: Mon | BK2: Tue | BL2: Wed | BM2: Thu | BN2: Fri | BO2: Sat | BP2: Sun | BS2: Interval | BT2: For next day | BU2: Mon | BV2: Tue | BW2: Wed | BX2: Thu | BY2: Fri | BZ2: Sat | CA2: Sun | CB2: Mon | CC2: Tue | CD2: Wed | CE2: Thu | CF2: Fri | CG2: Sat | CH2: Sun | CI2: Mon | CJ2: Tue | CK2: Wed | CL2: Thu | CM2: Fri | CN2: Sat | CO2: Sun
A3: ='Nesting Phone time'!B4 -> Jave Lowelle Valiente Gayangos | B3: =IFERROR(VLOOKUP(A3,'Nesting Phone time'!B:I,2,),"-") -> 0.58333333 | C3: =IFERROR(IF(B3="PTO", "PTO", IF(B3="OFF","OFF",B3 + TIME(9,0,0))),"-") -> 0.95833333 | D3: =IFERROR(VLOOKUP(A3,'Nesting Phone time'!B:I,3,),"-") -> OFF | E3: =IFERROR(IF(D3="PTO", "PTO", IF(D3="OFF","OFF",D3 + TIME(9,0,0))),"-") -> OFF | F3: =IFERROR(VLOOKUP(A3,'Nesting Phone time'!B:I,4,),"-") -> 0.58333333 | G3: =IFERROR(IF(F3="PTO", "PTO", IF(F3="OFF","OFF",F3 + TIME(9,0,0))),"-") -> 0.95833333 | H3: =IFERROR(VLOOKUP(A3,'Nesting Phone time'!B:I,5,),"-") -> 0.58333333 | I3: =IFERROR(IF(H3="PTO", "PTO", IF(H3="OFF","OFF",H3 + TIME(9,0,0))),"-") -> 0.95833333 | J3: =IFERROR(VLOOKUP(A3,'Nesting Phone time'!B:I,6,),"-") -> 0.58333333 | K3: =IFERROR(IF(J3="PTO", "PTO", IF(J3="OFF","OFF",J3 + TIME(9,0,0))),"-") -> 0.95833333 | L3: =IFERROR(VLOOKUP(A3,'Nesting Phone time'!B:I,7,),"-") -> OFF | M3: =IFERROR(IF(L3="PTO", "PTO", IF(L3="OFF","OFF",L3 + TIME(9,0,0))),"-") -> OFF | N3: =IFERROR(VLOOKUP(A3,'Nesting Phone time'!B:I,8,),"-") -> 0.58333333 | O3: =IFERROR(IF(N3="PTO", "PTO", IF(N3="OFF","OFF",N3 + TIME(9,0,0))),"-") -> 0.95833333 | Q3: =IFERROR(VLOOKUP(A3,'Nesting Phone time'!B:Y,24,),"-") -> 0.58333333 | R3: =IFERROR(IF(Q3="PTO", "PTO", IF(Q3="OFF","OFF",Q3 + TIME(9,0,0))),"-") -> 0.95833333 | T3: =IFERROR(VLOOKUP(A3,'Nesting Phone time'!$B:$J,9,),"-") -> 0.58333333 | U3: =IFERROR(IF(T3="PTO", "PTO", IF(T3="OFF","OFF",T3 + TIME(9,0,0))),"-") -> 0.95833333 | V3: =IFERROR(VLOOKUP(A3,'Nesting Phone time'!B:K,10,),"-") -> 0.58333333 | W3: =IFERROR(IF(V3="PTO", "PTO", IF(V3="OFF","OFF",V3 + TIME(9,0,0))),"-") -> 0.95833333 | X3: =IFERROR(VLOOKUP(A3,'Nesting Phone time'!B:L,11,),"-") -> 0.58333333 | Y3: =IFERROR(IF(X3="PTO", "PTO", IF(X3="OFF","OFF",X3 + TIME(9,0,0))),"-") -> 0.95833333 | Z3: =IFERROR(VLOOKUP(A3,'Nesting Phone time'!B:M,12,),"-") -> 0.58333333 | AA3: =IFERROR(IF(Z3="PTO", "PTO", IF(Z3="OFF","OFF",Z3 + TIME(9,0,0))),"-") -> 0.95833333 | AB3: =IFERROR(VLOOKUP(A3,'Nesting Phone time'!B:N,13,),"-") -> OFF | AC3: =IFERROR(IF(AB3="PTO", "PTO", IF(AB3="OFF","OFF",AB3 + TIME(9,0,0))),"-") -> OFF | AD3: =IFERROR(VLOOKUP(A3,'Nesting Phone time'!B:O,14,),"-") -> OFF | AE3: =IFERROR(IF(AD3="PTO", "PTO", IF(AD3="OFF","OFF",AD3 + TIME(9,0,0))),"-") -> OFF | AF3: =IFERROR(VLOOKUP(A3,'Nesting Phone time'!B:P,15,),"-") -> 0.58333333 | AG3: =IFERROR(IF(AF3="PTO", "PTO", IF(AF3="OFF","OFF",AF3 + TIME(9,0,0))),"-") -> 0.95833333 | AI3: =IFERROR(VLOOKUP(A3,'Nesting Phone time'!$B:$Q,16,),"-") -> 0.58333333 | AJ3: =IFERROR(IF(AI3="PTO", "PTO", IF(AI3="OFF","OFF",AI3 + TIME(9,0,0))),"-") -> 0.95833333 | AK3: =IFERROR(VLOOKUP(A3,'Nesting Phone time'!B:R,17,),"-") -> 0.58333333 | AL3: =IFERROR(IF(AK3="PTO", "PTO", IF(AK3="OFF","OFF",AK3 + TIME(9,0,0))),"-") -> 0.95833333 | AM3: =IFERROR(VLOOKUP(A3,'Nesting Phone time'!B:S,18,),"-") -> 0.58333333 | AN3: =IFERROR(IF(AM3="PTO", "PTO", IF(AM3="OFF","OFF",AM3 + TIME(9,0,0))),"-") -> 0.95833333 | AO3: =IFERROR(VLOOKUP(A3,'Nesting Phone time'!B:T,19,),"-") -> 0.58333333 | AP3: =IFERROR(IF(AO3="PTO", "PTO", IF(AO3="OFF","OFF",AO3 + TIME(9,0,0))),"-") -> 0.95833333 | AQ3: =IFERROR(VLOOKUP(A3,'Nesting Phone time'!B:U,20,),"-") -> OFF | AR3: =IFERROR(IF(AQ3="PTO", "PTO", IF(AQ3="OFF","OFF",AQ3 + TIME(9,0,0))),"-") -> OFF | AS3: =IFERROR(VLOOKUP(A3,'Nesting Phone time'!B:V,21,),"-") -> OFF | AT3: =IFERROR(IF(AS3="PTO", "PTO", IF(AS3="OFF","OFF",AS3 + TIME(9,0,0))),"-") -> OFF | AU3: =IFERROR(VLOOKUP(A3,'Nesting Phone time'!B:W,22,),"-") -> 0.58333333 | AV3: =IFERROR(IF(AU3="PTO", "PTO", IF(AU3="OFF","OFF",AU3 + TIME(9,0,0))),"-") -> 0.95833333 | AX3: 0 | AY3: 1 | AZ3: =(COUNTIFS($B$3:$B$12, "<=" & AX3, $C$3:$C$12, ">" & AX3))+COUNTIFS($Q$3:$Q$12, "<=" & AY3, $R$3:$R$12, ">" & AY3) -> 0 | BA3: =(COUNTIFS($D$3:$D$12, "<=" & AX3, $E$3:$E$12, ">" & AX3))+COUNTIFS($B$3:$B$12, "<=" & AY3, $C$3:$C$12, ">" & AY3) -> 0 | BB3: =(COUNTIFS($F$3:$F$12, "<=" & AX3, $G$3:$G$12, ">" & AX3))+COUNTIFS($D$3:$D$12, "<=" & AY3, $E$3:$E$12, ">" & AY3) -> 0 | BC3: =(COUNTIFS($H$3:$H$12, "<=" & AX3, $I$3:$I$12, ">" & AX3))+COUNTIFS($F$3:$F$12, "<=" & AY3, $G$3:$G$12, ">" & AY3) -> 0 | BD3: =(COUNTIFS($J$3:$J$12, "<=" & AX3, $K$3:$K$12, ">" & AX3))+COUNTIFS($H$3:$H$12, "<=" & AY3, $I$3:$I$12, ">" & AY3) -> 0 | BE3: =(COUNTIFS($L$3:$L$12, "<=" & AX3, $M$3:$M$12, ">" & AX3))+COUNTIFS($J$3:$J$12, "<=" & AY3, $K$3:$K$12, ">" & AY3) -> 0 | BF3: =(COUNTIFS($N$3:$N$12, "<=" & AX3, $O$3:$O$12, ">" & AX3))+COUNTIFS($L$3:$L$12, "<=" & AY3, $M$3:$M$12, ">" & AY3) -> 0 | BH3: 0 | BI3: 1 | BJ3: =(COUNTIFS($B$13:$B$37, "<=" & BH3, $C$13:$C$37, ">" & BH3))+COUNTIFS($Q$13:$Q$37, "<=" & BI3, $R$13:$R$37, ">" & BI3) -> 0 | BK3: =(COUNTIFS($D$13:$D$37, "<=" & BH3, $E$13:$E$37, ">" & BH3))+COUNTIFS($B$13:$B$37, "<=" & BI3, $C$13:$C$37, ">" & BI3) -> 0 | BL3: =(COUNTIFS($F$13:$F$37, "<=" & BH3, $G$13:$G$37, ">" & BH3))+COUNTIFS($D$13:$D$37, "<=" & BI3, $E$13:$E$37, ">" & BI3) -> 0 | BM3: =(COUNTIFS($H$13:$H$37, "<=" & BH3, $I$13:$I$37, ">" & BH3))+COUNTIFS($F$13:$F$37, "<=" & BI3, $G$13:$G$37, ">" & BI3) -> 0 | BN3: =(COUNTIFS($J$13:$J$37, "<=" & BH3, $K$13:$K$37, ">" & BH3))+COUNTIFS($H$13:$H$37, "<=" & BI3, $I$13:$I$37, ">" & BI3) -> 0 | BO3: =(COUNTIFS($L$13:$L$37, "<=" & BH3, $M$13:$M$37, ">" & BH3))+COUNTIFS($J$13:$J$37, "<=" & BI3, $K$13:$K$37, ">" & BI3) -> 0 | BP3: =(COUNTIFS($N$13:$N$37, "<=" & BH3, $O$13:$O$37, ">" & BH3))+COUNTIFS($L$13:$L$37, "<=" & BI3, $M$13:$M$37, ">" & BI3) -> 0 | BS3: 0 | BT3: 1 | BU3: =COUNTIFS(Q:Q, "<=" & BT3, R:R, ">" & BT3)+COUNTIFS(B:B, "<=" & BS3, C:C, ">" & BS3) -> 0 | BV3: =COUNTIFS(B:B, "<=" & BT3, C:C, ">" & BT3)+COUNTIFS(D:D, "<=" & BS3, E:E, ">" & BS3) -> 0 | BW3: =COUNTIFS(D:D, "<=" & BT3, E:E, ">" & BT3)+COUNTIFS(F:F, "<=" & BS3, G:G, ">" & BS3) -> 0 | BX3: =COUNTIFS(F:F, "<=" & BT3, G:G, ">" & BT3)+COUNTIFS(H:H, "<=" & BS3, I:I, ">" & BS3) -> 0 | BY3: =COUNTIFS(H:H, "<=" & BT3, I:I, ">" & BT3)+COUNTIFS(J:J, "<=" & BS3, K:K, ">" & BS3) -> 0 | BZ3: =COUNTIFS(J:J, "<=" & BT3, K:K, ">" & BT3)+COUNTIFS(L:L, "<=" & BS3, M:M, ">" & BS3) -> 0 | CA3: =COUNTIFS(N:N, "<=" & BS3, O:O, ">" & BS3)+COUNTIFS(L:L, "<=" & BT3, M:M, ">" & BT3) -> 0 | CB3: =COUNTIFS(T:T, "<=" & BS3, U:U, ">" & BS3)+COUNTIFS(N:N, "<=" & BT3, O:O, ">" & BT3) -> 0 | CC3: =COUNTIFS(V:V, "<=" & BS3, W:W, ">" & BS3)+COUNTIFS(T:T, "<=" & BT3, U:U, ">" & BT3) -> 0 | CD3: =COUNTIFS(X:X, "<=" & BS3, Y:Y, ">" & BS3)+COUNTIFS(V:V, "<=" & BT3, W:W, ">" & BT3) -> 0 | CE3: =COUNTIFS(Z:Z, "<=" & BS3, AA:AA, ">" & BS3)+COUNTIFS(X:X, "<=" & BT3, Y:Y, ">" & BT3) -> 0 | CF3: =COUNTIFS(AB:AB, "<=" & BS3, AC:AC, ">" & BS3)+COUNTIFS(Z:Z, "<=" & BT3, AA:AA, ">" & BT3) -> 0 | CG3: =COUNTIFS(AD:AD, "<=" & BS3, AE:AE, ">" & BS3)+COUNTIFS(AB:AB, "<=" & BT3, AC:AC, ">" & BT3) -> 0 | CH3: =COUNTIFS(AF:AF, "<=" & BS3, AG:AG, ">" & BS3)+COUNTIFS(AD:AD, "<=" & BT3, AE:AE, ">" & BT3) -> 0 | CI3: =COUNTIFS(AI:AI, "<=" & BS3, AJ:AJ, ">" & BS3)+COUNTIFS(AF:AF, "<=" & BT3, AG:AG, ">" & BT3) -> 0 | CJ3: =COUNTIFS(AK:AK, "<=" & BS3, AL:AL, ">" & BS3)+COUNTIFS(AI:AI, "<=" & BT3, AJ:AJ, ">" & BT3) -> 0 | CK3: =COUNTIFS(AM:AM, "<=" & BS3, AN:AN, ">" & BS3)+COUNTIFS(AK:AK, "<=" & BT3, AL:AL, ">" & BT3) -> 0 | CL3: =COUNTIFS(AO:AO, "<=" & BS3, AP:AP, ">" & BS3)+COUNTIFS(AM:AM, "<=" & BT3, AN:AN, ">" & BT3) -> 0 | CM3: =COUNTIFS(AQ:AQ, "<=" & BS3, AR:AR, ">" & BS3)+COUNTIFS(AO:AO, "<=" & BT3, AP:AP, ">" & BT3) -> 0 | CN3: =COUNTIFS(AS:AS, "<=" & BS3, AT:AT, ">" & BS3)+COUNTIFS(AQ:AQ, "<=" & BT3, AR:AR, ">" & BT3) -> 0 | CO3: =COUNTIFS(AU:AU, "<=" & BS3, AV:AV, ">" & BS3)+COUNTIFS(AS:AS, "<=" & BT3, AT:AT, ">" & BT3) -> 0
